Workbook

Sheet Hitter Stats
A1: MLBAMID | B1: Hitter | C1: Pitches Faced | D1: Swings | E1: BBE | F1: Swing Aggression | G1: Strikezone Judgement+ | H1: Decision Value+ | I1: zDV+ | J1: oDV+ | K1: Contact Ability+ | L1: Power+ | M1: Process+ | N1: Hitter Performance | O1: Regressed DV | P1: Regressed CA | Q1: Regressed Power | R1: Regressed Process
A2: 592450 | B2: Aaron Judge | C2: 1642 | D2: 751 | E2: 246 | F2: -0.04 | G2: 110 | H2: 115 | I2: 99 | J2: 115 | K2: 91 | L2: 153 | M2: 150 | N2: 158 | O2: =(H2*C2+400*100)/(C2+400) -> 112.0617 | P2: =(K2*D2+200*100)/(D2+200) -> 92.892744 | Q2: =(L2*E2+75*100)/(E2+75) -> 140.61682 | R2: =(M2*C2+400*100)/(C2+400) -> 140.20568
A3: 665742 | B3: Juan Soto | C3: 1815 | D3: 625 | E3: 266 | F3: -0.131 | G3: 108 | H3: 134 | I3: 88 | J3: 137 | K3: 99 | L3: 137 | M3: 147 | N3: 126 | O3: =(H3*C3+400*100)/(C3+400) -> 127.86005 | P3: =(K3*D3+200*100)/(D3+200) -> 99.242424 | Q3: =(L3*E3+75*100)/(E3+75) -> 128.86217 | R3: =(M3*C3+400*100)/(C3+400) -> 138.51242
A4: 660271 | B4: Shohei Ohtani | C4: 1715 | D4: 763 | E4: 261 | F4: -0.026 | G4: 104 | H4: 102 | I4: 86 | J4: 106 | K4: 88 | L4: 146 | M4: 137 | N4: 130 | O4: =(H4*C4+400*100)/(C4+400) -> 101.62175 | P4: =(K4*D4+200*100)/(D4+200) -> 90.492212 | Q4: =(L4*E4+75*100)/(E4+75) -> 135.73214 | R4: =(M4*C4+400*100)/(C4+400) -> 130.00236
A5: 624413 | B5: Pete Alonso | C5: 1731 | D5: 788 | E5: 268 | F5: -0.033 | G5: 102 | H5: 110 | I5: 103 | J5: 108 | K5: 95 | L5: 136 | M5: 136 | N5: 127 | O5: =(H5*C5+400*100)/(C5+400) -> 108.12295 | P5: =(K5*D5+200*100)/(D5+200) -> 96.012146 | Q5: =(L5*E5+75*100)/(E5+75) -> 128.12828 | R5: =(M5*C5+400*100)/(C5+400) -> 129.24261
A6: 660670 | B6: Ronald Acuña Jr. | C6: 814 | D6: 356 | E6: 109 | F6: -0.049 | G6: 121 | H6: 134 | I6: 116 | J6: 126 | K6: 79 | L6: 137 | M6: 135 | N6: 142 | O6: =(H6*C6+400*100)/(C6+400) -> 122.79736 | P6: =(K6*D6+200*100)/(D6+200) -> 86.553957 | Q6: =(L6*E6+75*100)/(E6+75) -> 121.91848 | R6: =(M6*C6+400*100)/(C6+400) -> 123.46787
A7: 545361 | B7: Mike Trout | C7: 1307 | D7: 507 | E7: 167 | F7: -0.123 | G7: 110 | H7: 130 | I7: 101 | J7: 129 | K7: 91 | L7: 130 | M7: 132 | N7: 121 | O7: =(H7*C7+400*100)/(C7+400) -> 122.97012 | P7: =(K7*D7+200*100)/(D7+200) -> 93.545969 | Q7: =(L7*E7+75*100)/(E7+75) -> 120.70248 | R7: =(M7*C7+400*100)/(C7+400) -> 124.50146
A8: 543807 | B8: George Springer | C8: 1411 | D8: 631 | E8: 234 | F8: -0.045 | G8: 129 | H8: 130 | I8: 107 | J8: 127 | K8: 102 | L8: 116 | M8: 130 | N8: 121 | O8: =(H8*C8+400*100)/(C8+400) -> 123.37383 | P8: =(K8*D8+200*100)/(D8+200) -> 101.51865 | Q8: =(L8*E8+75*100)/(E8+75) -> 112.1165 | R8: =(M8*C8+400*100)/(C8+400) -> 123.37383
A9: 650402 | B9: Gleyber Torres | C9: 1468 | D9: 599 | E9: 258 | F9: -0.084 | G9: 128 | H9: 142 | I9: 105 | J9: 138 | K9: 109 | L9: 107 | M9: 130 | N9: 121 | O9: =(H9*C9+400*100)/(C9+400) -> 133.00642 | P9: =(K9*D9+200*100)/(D9+200) -> 106.74718 | Q9: =(L9*E9+75*100)/(E9+75) -> 105.42342 | R9: =(M9*C9+400*100)/(C9+400) -> 123.57602
A10: 683737 | B10: Michael Busch | C10: 1370 | D10: 636 | E10: 222 | F10: -0.028 | G10: 118 | H10: 115 | I10: 94 | J10: 117 | K10: 93 | L10: 127 | M10: 130 | N10: 129 | O10: =(H10*C10+400*100)/(C10+400) -> 111.61017 | P10: =(K10*D10+200*100)/(D10+200) -> 94.674641 | Q10: =(L10*E10+75*100)/(E10+75) -> 120.18182 | R10: =(M10*C10+400*100)/(C10+400) -> 123.22034
A11: 608369 | B11: Corey Seager | C11: 1067 | D11: 534 | E11: 184 | F11: 0.044 | G11: 132 | H11: 107 | I11: 108 | J11: 103 | K11: 97 | L11: 126 | M11: 129 | N11: 115 | O11: =(H11*C11+400*100)/(C11+400) -> 105.09134 | P11: =(K11*D11+200*100)/(D11+200) -> 97.817439 | Q11: =(L11*E11+75*100)/(E11+75) -> 118.47104 | R11: =(M11*C11+400*100)/(C11+400) -> 121.09271
A12: 663853 | B12: Romy González | C12: 546 | D12: 289 | E12: 109 | F12: 0.053 | G12: 100 | H12: 83 | I12: 104 | J12: 83 | K12: 110 | L12: 125 | M12: 129 | N12: 126 | O12: =(H12*C12+400*100)/(C12+400) -> 90.188161 | P12: =(K12*D12+200*100)/(D12+200) -> 105.91002 | Q12: =(L12*E12+75*100)/(E12+75) -> 114.80978 | R12: =(M12*C12+400*100)/(C12+400) -> 116.73784
A13: 666176 | B13: Jo Adell | C13: 1232 | D13: 642 | E13: 215 | F13: 0.03 | G13: 110 | H13: 102 | I13: 107 | J13: 99 | K13: 98 | L13: 126 | M13: 128 | N13: 111 | O13: =(H13*C13+400*100)/(C13+400) -> 101.5098 | P13: =(K13*D13+200*100)/(D13+200) -> 98.475059 | Q13: =(L13*E13+75*100)/(E13+75) -> 119.27586 | R13: =(M13*C13+400*100)/(C13+400) -> 121.13725
... A369: 678877 | B369: Jhonkensy Noel | C369: 415 | D369: 247 | E369: 73 | F369: 0.134 | G369: 87 | H369: 52 | I369: 124 | J369: 52 | K369: 95 | L369: 76 | M369: 53 | N369: 43 | O369: =(H369*C369+400*100)/(C369+400) -> 75.558282 | P369: =(K369*D369+200*100)/(D369+200) -> 97.237136 | Q369: =(L369*E369+75*100)/(E369+75) -> 88.162162 | R369: =(M369*C369+400*100)/(C369+400) -> 76.067485

Sheet vs Last Year
A1: =IFERROR(__xludf.DUMMYFUNCTION("FILTER('Hitter Stats'!A:A, arrayformula(ISNUMBER(MATCH('Hitter Stats'!A:A,'2024'!A:A,0))))"),"MLBAMID") -> MLBAMID | B1: Hitter | C1: Δ Swing Aggression | D1: Δ Decision Value+ | E1: Δ Contact Ability+ | F1: Δ Power+ | G1: Δ Process+
A2: =IFERROR(__xludf.DUMMYFUNCTION("""COMPUTED_VALUE"""),592450.0) -> 592450 | B2: {=index('Hitter Stats'!B:B,match(A2,'Hitter Stats'!A:A,0))} -> Aaron Judge | C2: {=index('Hitter Stats'!F:F,match($A2,'Hitter Stats'!$A:$A,0))-index('2024'!F:F,match($A2,'2024'!$A:$A,0))} -> 0.031494324 | D2: {=index('Hitter Stats'!H:H,match($A2,'Hitter Stats'!$A:$A,0))-index('2024'!H:H,match($A2,'2024'!$A:$A,0))} -> -21 | E2: {=index('Hitter Stats'!K:K,match($A2,'Hitter Stats'!$A:$A,0))-index('2024'!K:K,match($A2,'2024'!$A:$A,0))} -> -1 | F2: {=index('Hitter Stats'!L:L,match($A2,'Hitter Stats'!$A:$A,0))-index('2024'!L:L,match($A2,'2024'!$A:$A,0))} -> -5 | G2: {=index('Hitter Stats'!M:M,match($A2,'Hitter Stats'!$A:$A,0))-index('2024'!M:M,match($A2,'2024'!$A:$A,0))} -> -11
A3: =IFERROR(__xludf.DUMMYFUNCTION("""COMPUTED_VALUE"""),665742.0) -> 665742 | B3: {=index('Hitter Stats'!B:B,match(A3,'Hitter Stats'!A:A,0))} -> Juan Soto | C3: {=index('Hitter Stats'!F:F,match($A3,'Hitter Stats'!$A:$A,0))-index('2024'!F:F,match($A3,'2024'!$A:$A,0))} -> -0.056528718 | D3: {=index('Hitter Stats'!H:H,match($A3,'Hitter Stats'!$A:$A,0))-index('2024'!H:H,match($A3,'2024'!$A:$A,0))} -> 3 | E3: {=index('Hitter Stats'!K:K,match($A3,'Hitter Stats'!$A:$A,0))-index('2024'!K:K,match($A3,'2024'!$A:$A,0))} -> -1 | F3: {=index('Hitter Stats'!L:L,match($A3,'Hitter Stats'!$A:$A,0))-index('2024'!L:L,match($A3,'2024'!$A:$A,0))} -> -12 | G3: {=index('Hitter Stats'!M:M,match($A3,'Hitter Stats'!$A:$A,0))-index('2024'!M:M,match($A3,'2024'!$A:$A,0))} -> -13
A4: =IFERROR(__xludf.DUMMYFUNCTION("""COMPUTED_VALUE"""),660271.0) -> 660271 | B4: {=index('Hitter Stats'!B:B,match(A4,'Hitter Stats'!A:A,0))} -> Shohei Ohtani | C4: {=index('Hitter Stats'!F:F,match($A4,'Hitter Stats'!$A:$A,0))-index('2024'!F:F,match($A4,'2024'!$A:$A,0))} -> -0.035351378 | D4: {=index('Hitter Stats'!H:H,match($A4,'Hitter Stats'!$A:$A,0))-index('2024'!H:H,match($A4,'2024'!$A:$A,0))} -> 10 | E4: {=index('Hitter Stats'!K:K,match($A4,'Hitter Stats'!$A:$A,0))-index('2024'!K:K,match($A4,'2024'!$A:$A,0))} -> -10 | F4: {=index('Hitter Stats'!L:L,match($A4,'Hitter Stats'!$A:$A,0))-index('2024'!L:L,match($A4,'2024'!$A:$A,0))} -> -9 | G4: {=index('Hitter Stats'!M:M,match($A4,'Hitter Stats'!$A:$A,0))-index('2024'!M:M,match($A4,'2024'!$A:$A,0))} -> -12
A5: =IFERROR(__xludf.DUMMYFUNCTION("""COMPUTED_VALUE"""),624413.0) -> 624413 | B5: {=index('Hitter Stats'!B:B,match(A5,'Hitter Stats'!A:A,0))} -> Pete Alonso | C5: {=index('Hitter Stats'!F:F,match($A5,'Hitter Stats'!$A:$A,0))-index('2024'!F:F,match($A5,'2024'!$A:$A,0))} -> 0.025634912 | D5: {=index('Hitter Stats'!H:H,match($A5,'Hitter Stats'!$A:$A,0))-index('2024'!H:H,match($A5,'2024'!$A:$A,0))} -> 4 | E5: {=index('Hitter Stats'!K:K,match($A5,'Hitter Stats'!$A:$A,0))-index('2024'!K:K,match($A5,'2024'!$A:$A,0))} -> -8 | F5: {=index('Hitter Stats'!L:L,match($A5,'Hitter Stats'!$A:$A,0))-index('2024'!L:L,match($A5,'2024'!$A:$A,0))} -> 16 | G5: {=index('Hitter Stats'!M:M,match($A5,'Hitter Stats'!$A:$A,0))-index('2024'!M:M,match($A5,'2024'!$A:$A,0))} -> 12
A6: =IFERROR(__xludf.DUMMYFUNCTION("""COMPUTED_VALUE"""),660670.0) -> 660670 | B6: {=index('Hitter Stats'!B:B,match(A6,'Hitter Stats'!A:A,0))} -> Ronald Acuña Jr. | C6: {=index('Hitter Stats'!F:F,match($A6,'Hitter Stats'!$A:$A,0))-index('2024'!F:F,match($A6,'2024'!$A:$A,0))} -> -0.010444394 | D6: {=index('Hitter Stats'!H:H,match($A6,'Hitter Stats'!$A:$A,0))-index('2024'!H:H,match($A6,'2024'!$A:$A,0))} -> 12 | E6: {=index('Hitter Stats'!K:K,match($A6,'Hitter Stats'!$A:$A,0))-index('2024'!K:K,match($A6,'2024'!$A:$A,0))} -> -2 | F6: {=index('Hitter Stats'!L:L,match($A6,'Hitter Stats'!$A:$A,0))-index('2024'!L:L,match($A6,'2024'!$A:$A,0))} -> 27 | G6: {=index('Hitter Stats'!M:M,match($A6,'Hitter Stats'!$A:$A,0))-index('2024'!M:M,match($A6,'2024'!$A:$A,0))} -> 25
A7: =IFERROR(__xludf.DUMMYFUNCTION("""COMPUTED_VALUE"""),545361.0) -> 545361 | B7: {=index('Hitter Stats'!B:B,match(A7,'Hitter Stats'!A:A,0))} -> Mike Trout | C7: {=index('Hitter Stats'!F:F,match($A7,'Hitter Stats'!$A:$A,0))-index('2024'!F:F,match($A7,'2024'!$A:$A,0))} -> -0.024878802 | D7: {=index('Hitter Stats'!H:H,match($A7,'Hitter Stats'!$A:$A,0))-index('2024'!H:H,match($A7,'2024'!$A:$A,0))} -> -8 | E7: {=index('Hitter Stats'!K:K,match($A7,'Hitter Stats'!$A:$A,0))-index('2024'!K:K,match($A7,'2024'!$A:$A,0))} -> -3 | F7: {=index('Hitter Stats'!L:L,match($A7,'Hitter Stats'!$A:$A,0))-index('2024'!L:L,match($A7,'2024'!$A:$A,0))} -> 1 | G7: {=index('Hitter Stats'!M:M,match($A7,'Hitter Stats'!$A:$A,0))-index('2024'!M:M,match($A7,'2024'!$A:$A,0))} -> -9
A8: =IFERROR(__xludf.DUMMYFUNCTION("""COMPUTED_VALUE"""),543807.0) -> 543807 | B8: {=index('Hitter Stats'!B:B,match(A8,'Hitter Stats'!A:A,0))} -> George Springer | C8: {=index('Hitter Stats'!F:F,match($A8,'Hitter Stats'!$A:$A,0))-index('2024'!F:F,match($A8,'2024'!$A:$A,0))} -> -0.03191522 | D8: {=index('Hitter Stats'!H:H,match($A8,'Hitter Stats'!$A:$A,0))-index('2024'!H:H,match($A8,'2024'!$A:$A,0))} -> -8 | E8: {=index('Hitter Stats'!K:K,match($A8,'Hitter Stats'!$A:$A,0))-index('2024'!K:K,match($A8,'2024'!$A:$A,0))} -> 2 | F8: {=index('Hitter Stats'!L:L,match($A8,'Hitter Stats'!$A:$A,0))-index('2024'!L:L,match($A8,'2024'!$A:$A,0))} -> 25 | G8: {=index('Hitter Stats'!M:M,match($A8,'Hitter Stats'!$A:$A,0))-index('2024'!M:M,match($A8,'2024'!$A:$A,0))} -> 20
A9: =IFERROR(__xludf.DUMMYFUNCTION("""COMPUTED_VALUE"""),650402.0) -> 650402 | B9: {=index('Hitter Stats'!B:B,match(A9,'Hitter Stats'!A:A,0))} -> Gleyber Torres | C9: {=index('Hitter Stats'!F:F,match($A9,'Hitter Stats'!$A:$A,0))-index('2024'!F:F,match($A9,'2024'!$A:$A,0))} -> -0.037591473 | D9: {=index('Hitter Stats'!H:H,match($A9,'Hitter Stats'!$A:$A,0))-index('2024'!H:H,match($A9,'2024'!$A:$A,0))} -> 17 | E9: {=index('Hitter Stats'!K:K,match($A9,'Hitter Stats'!$A:$A,0))-index('2024'!K:K,match($A9,'2024'!$A:$A,0))} -> 9 | F9: {=index('Hitter Stats'!L:L,match($A9,'Hitter Stats'!$A:$A,0))-index('2024'!L:L,match($A9,'2024'!$A:$A,0))} -> 11 | G9: {=index('Hitter Stats'!M:M,match($A9,'Hitter Stats'!$A:$A,0))-index('2024'!M:M,match($A9,'2024'!$A:$A,0))} -> 21
A10: =IFERROR(__xludf.DUMMYFUNCTION("""COMPUTED_VALUE"""),683737.0) -> 683737 | B10: {=index('Hitter Stats'!B:B,match(A10,'Hitter Stats'!A:A,0))} -> Michael Busch | C10: {=index('Hitter Stats'!F:F,match($A10,'Hitter Stats'!$A:$A,0))-index('2024'!F:F,match($A10,'2024'!$A:$A,0))} -> -0.011556007 | D10: {=index('Hitter Stats'!H:H,match($A10,'Hitter Stats'!$A:$A,0))-index('2024'!H:H,match($A10,'2024'!$A:$A,0))} -> 9 | E10: {=index('Hitter Stats'!K:K,match($A10,'Hitter Stats'!$A:$A,0))-index('2024'!K:K,match($A10,'2024'!$A:$A,0))} -> 10 | F10: {=index('Hitter Stats'!L:L,match($A10,'Hitter Stats'!$A:$A,0))-index('2024'!L:L,match($A10,'2024'!$A:$A,0))} -> 12 | G10: {=index('Hitter Stats'!M:M,match($A10,'Hitter Stats'!$A:$A,0))-index('2024'!M:M,match($A10,'2024'!$A:$A,0))} -> 23
A11: =IFERROR(__xludf.DUMMYFUNCTION("""COMPUTED_VALUE"""),608369.0) -> 608369 | B11: {=index('Hitter Stats'!B:B,match(A11,'Hitter Stats'!A:A,0))} -> Corey Seager | C11: {=index('Hitter Stats'!F:F,match($A11,'Hitter Stats'!$A:$A,0))-index('2024'!F:F,match($A11,'2024'!$A:$A,0))} -> -0.014142568 | D11: {=index('Hitter Stats'!H:H,match($A11,'Hitter Stats'!$A:$A,0))-index('2024'!H:H,match($A11,'2024'!$A:$A,0))} -> -2 | E11: {=index('Hitter Stats'!K:K,match($A11,'Hitter Stats'!$A:$A,0))-index('2024'!K:K,match($A11,'2024'!$A:$A,0))} -> -2 | F11: {=index('Hitter Stats'!L:L,match($A11,'Hitter Stats'!$A:$A,0))-index('2024'!L:L,match($A11,'2024'!$A:$A,0))} -> -2 | G11: {=index('Hitter Stats'!M:M,match($A11,'Hitter Stats'!$A:$A,0))-index('2024'!M:M,match($A11,'2024'!$A:$A,0))} -> -8
A12: =IFERROR(__xludf.DUMMYFUNCTION("""COMPUTED_VALUE"""),663853.0) -> 663853 | B12: {=index('Hitter Stats'!B:B,match(A12,'Hitter Stats'!A:A,0))} -> Romy González | C12: {=index('Hitter Stats'!F:F,match($A12,'Hitter Stats'!$A:$A,0))-index('2024'!F:F,match($A12,'2024'!$A:$A,0))} -> 0.007405749 | D12: {=index('Hitter Stats'!H:H,match($A12,'Hitter Stats'!$A:$A,0))-index('2024'!H:H,match($A12,'2024'!$A:$A,0))} -> -9 | E12: {=index('Hitter Stats'!K:K,match($A12,'Hitter Stats'!$A:$A,0))-index('2024'!K:K,match($A12,'2024'!$A:$A,0))} -> 12 | F12: {=index('Hitter Stats'!L:L,match($A12,'Hitter Stats'!$A:$A,0))-index('2024'!L:L,match($A12,'2024'!$A:$A,0))} -> 21 | G12: {=index('Hitter Stats'!M:M,match($A12,'Hitter Stats'!$A:$A,0))-index('2024'!M:M,match($A12,'2024'!$A:$A,0))} -> 29
A13: =IFERROR(__xludf.DUMMYFUNCTION("""COMPUTED_VALUE"""),666176.0) -> 666176 | B13: {=index('Hitter Stats'!B:B,match(A13,'Hitter Stats'!A:A,0))} -> Jo Adell | C13: {=index('Hitter Stats'!F:F,match($A13,'Hitter Stats'!$A:$A,0))-index('2024'!F:F,match($A13,'2024'!$A:$A,0))} -> 0.029297328 | D13: {=index('Hitter Stats'!H:H,match($A13,'Hitter Stats'!$A:$A,0))-index('2024'!H:H,match($A13,'2024'!$A:$A,0))} -> -1 | E13: {=index('Hitter Stats'!K:K,match($A13,'Hitter Stats'!$A:$A,0))-index('2024'!K:K,match($A13,'2024'!$A:$A,0))} -> 5 | F13: {=index('Hitter Stats'!L:L,match($A13,'Hitter Stats'!$A:$A,0))-index('2024'!L:L,match($A13,'2024'!$A:$A,0))} -> 24 | G13: {=index('Hitter Stats'!M:M,match($A13,'Hitter Stats'!$A:$A,0))-index('2024'!M:M,match($A13,'2024'!$A:$A,0))} -> 28
A14: =IFERROR(__xludf.DUMMYFUNCTION("""COMPUTED_VALUE"""),592518.0) -> 592518 | B14: {=index('Hitter Stats'!B:B,match(A14,'Hitter Stats'!A:A,0))} -> Manny Machado | C14: {=index('Hitter Stats'!F:F,match($A14,'Hitter Stats'!$A:$A,0))-index('2024'!F:F,match($A14,'2024'!$A:$A,0))} -> -0.014340139 | D14: {=index('Hitter Stats'!H:H,match($A14,'Hitter Stats'!$A:$A,0))-index('2024'!H:H,match($A14,'2024'!$A:$A,0))} -> -5 | E14: {=index('Hitter Stats'!K:K,match($A14,'Hitter Stats'!$A:$A,0))-index('2024'!K:K,match($A14,'2024'!$A:$A,0))} -> 6 | F14: {=index('Hitter Stats'!L:L,match($A14,'Hitter Stats'!$A:$A,0))-index('2024'!L:L,match($A14,'2024'!$A:$A,0))} -> 8 | G14: {=index('Hitter Stats'!M:M,match($A14,'Hitter Stats'!$A:$A,0))-index('2024'!M:M,match($A14,'2024'!$A:$A,0))} -> 9
A15: =IFERROR(__xludf.DUMMYFUNCTION("""COMPUTED_VALUE"""),700250.0) -> 700250 | B15: {=index('Hitter Stats'!B:B,match(A15,'Hitter Stats'!A:A,0))} -> Ben Rice | C15: {=index('Hitter Stats'!F:F,match($A15,'Hitter Stats'!$A:$A,0))-index('2024'!F:F,match($A15,'2024'!$A:$A,0))} -> 0.012593897 | D15: {=index('Hitter Stats'!H:H,match($A15,'Hitter Stats'!$A:$A,0))-index('2024'!H:H,match($A15,'2024'!$A:$A,0))} -> -14 | E15: {=index('Hitter Stats'!K:K,match($A15,'Hitter Stats'!$A:$A,0))-index('2024'!K:K,match($A15,'2024'!$A:$A,0))} -> 15 | F15: {=index('Hitter Stats'!L:L,match($A15,'Hitter Stats'!$A:$A,0))-index('2024'!L:L,match($A15,'2024'!$A:$A,0))} -> 8 | G15: {=index('Hitter Stats'!M:M,match($A15,'Hitter Stats'!$A:$A,0))-index('2024'!M:M,match($A15,'2024'!$A:$A,0))} -> 12
A16: =IFERROR(__xludf.DUMMYFUNCTION("""COMPUTED_VALUE"""),665489.0) -> 665489 | B16: {=index('Hitter Stats'!B:B,match(A16,'Hitter Stats'!A:A,0))} -> Vladimir Guerrero Jr. | C16: {=index('Hitter Stats'!F:F,match($A16,'Hitter Stats'!$A:$A,0))-index('2024'!F:F,match($A16,'2024'!$A:$A,0))} -> -0.053443858 | D16: {=index('Hitter Stats'!H:H,match($A16,'Hitter Stats'!$A:$A,0))-index('2024'!H:H,match($A16,'2024'!$A:$A,0))} -> 6 | E16: {=index('Hitter Stats'!K:K,match($A16,'Hitter Stats'!$A:$A,0))-index('2024'!K:K,match($A16,'2024'!$A:$A,0))} -> 0 | F16: {=index('Hitter Stats'!L:L,match($A16,'Hitter Stats'!$A:$A,0))-index('2024'!L:L,match($A16,'2024'!$A:$A,0))} -> -14 | G16: {=index('Hitter Stats'!M:M,match($A16,'Hitter Stats'!$A:$A,0))-index('2024'!M:M,match($A16,'2024'!$A:$A,0))} -> -16
A17: =IFERROR(__xludf.DUMMYFUNCTION("""COMPUTED_VALUE"""),650490.0) -> 650490 | B17: {=index('Hitter Stats'!B:B,match(A17,'Hitter Stats'!A:A,0))} -> Yandy Díaz | C17: {=index('Hitter Stats'!F:F,match($A17,'Hitter Stats'!$A:$A,0))-index('2024'!F:F,match($A17,'2024'!$A:$A,0))} -> 0.017333184 | D17: {=index('Hitter Stats'!H:H,match($A17,'Hitter Stats'!$A:$A,0))-index('2024'!H:H,match($A17,'2024'!$A:$A,0))} -> -8 | E17: {=index('Hitter Stats'!K:K,match($A17,'Hitter Stats'!$A:$A,0))-index('2024'!K:K,match($A17,'2024'!$A:$A,0))} -> -5 | F17: {=index('Hitter Stats'!L:L,match($A17,'Hitter Stats'!$A:$A,0))-index('2024'!L:L,match($A17,'2024'!$A:$A,0))} -> 10 | G17: {=index('Hitter Stats'!M:M,match($A17,'Hitter Stats'!$A:$A,0))-index('2024'!M:M,match($A17,'2024'!$A:$A,0))} -> 4
A18: =IFERROR(__xludf.DUMMYFUNCTION("""COMPUTED_VALUE"""),669257.0) -> 669257 | B18: {=index('Hitter Stats'!B:B,match(A18,'Hitter Stats'!A:A,0))} -> Will Smith | C18: {=index('Hitter Stats'!F:F,match($A18,'Hitter Stats'!$A:$A,0))-index('2024'!F:F,match($A18,'2024'!$A:$A,0))} -> -0.086341094 | D18: {=index('Hitter Stats'!H:H,match($A18,'Hitter Stats'!$A:$A,0))-index('2024'!H:H,match($A18,'2024'!$A:$A,0))} -> 23 | E18: {=index('Hitter Stats'!K:K,match($A18,'Hitter Stats'!$A:$A,0))-index('2024'!K:K,match($A18,'2024'!$A:$A,0))} -> -1 | F18: {=index('Hitter Stats'!L:L,match($A18,'Hitter Stats'!$A:$A,0))-index('2024'!L:L,match($A18,'2024'!$A:$A,0))} -> 10 | G18: {=index('Hitter Stats'!M:M,match($A18,'Hitter Stats'!$A:$A,0))-index('2024'!M:M,match($A18,'2024'!$A:$A,0))} -> 17
A19: =IFERROR(__xludf.DUMMYFUNCTION("""COMPUTED_VALUE"""),672386.0) -> 672386 | B19: {=index('Hitter Stats'!B:B,match(A19,'Hitter Stats'!A:A,0))} -> Alejandro Kirk | C19: {=index('Hitter Stats'!F:F,match($A19,'Hitter Stats'!$A:$A,0))-index('2024'!F:F,match($A19,'2024'!$A:$A,0))} -> -0.010602024 | D19: {=index('Hitter Stats'!H:H,match($A19,'Hitter Stats'!$A:$A,0))-index('2024'!H:H,match($A19,'2024'!$A:$A,0))} -> 4 | E19: {=index('Hitter Stats'!K:K,match($A19,'Hitter Stats'!$A:$A,0))-index('2024'!K:K,match($A19,'2024'!$A:$A,0))} -> 3 | F19: {=index('Hitter Stats'!L:L,match($A19,'Hitter Stats'!$A:$A,0))-index('2024'!L:L,match($A19,'2024'!$A:$A,0))} -> 7 | G19: {=index('Hitter Stats'!M:M,match($A19,'Hitter Stats'!$A:$A,0))-index('2024'!M:M,match($A19,'2024'!$A:$A,0))} -> 12
A20: =IFERROR(__xludf.DUMMYFUNCTION("""COMPUTED_VALUE"""),673548.0) -> 673548 | B20: {=index('Hitter Stats'!B:B,match(A20,'Hitter Stats'!A:A,0))} -> Seiya Suzuki | C20: {=index('Hitter Stats'!F:F,match($A20,'Hitter Stats'!$A:$A,0))-index('2024'!F:F,match($A20,'2024'!$A:$A,0))} -> 0.001047093 | D20: {=index('Hitter Stats'!H:H,match($A20,'Hitter Stats'!$A:$A,0))-index('2024'!H:H,match($A20,'2024'!$A:$A,0))} -> -3 | E20: {=index('Hitter Stats'!K:K,match($A20,'Hitter Stats'!$A:$A,0))-index('2024'!K:K,match($A20,'2024'!$A:$A,0))} -> 0 | F20: {=index('Hitter Stats'!L:L,match($A20,'Hitter Stats'!$A:$A,0))-index('2024'!L:L,match($A20,'2024'!$A:$A,0))} -> 8 | G20: {=index('Hitter Stats'!M:M,match($A20,'Hitter Stats'!$A:$A,0))-index('2024'!M:M,match($A20,'2024'!$A:$A,0))} -> 9
A21: =IFERROR(__xludf.DUMMYFUNCTION("""COMPUTED_VALUE"""),695578.0) -> 695578 | B21: {=index('Hitter Stats'!B:B,match(A21,'Hitter Stats'!A:A,0))} -> James Wood | C21: {=index('Hitter Stats'!F:F,match($A21,'Hitter Stats'!$A:$A,0))-index('2024'!F:F,match($A21,'2024'!$A:$A,0))} -> -0.000804961 | D21: {=index('Hitter Stats'!H:H,match($A21,'Hitter Stats'!$A:$A,0))-index('2024'!H:H,match($A21,'2024'!$A:$A,0))} -> -1 | E21: {=index('Hitter Stats'!K:K,match($A21,'Hitter Stats'!$A:$A,0))-index('2024'!K:K,match($A21,'2024'!$A:$A,0))} -> -2 | F21: {=index('Hitter Stats'!L:L,match($A21,'Hitter Stats'!$A:$A,0))-index('2024'!L:L,match($A21,'2024'!$A:$A,0))} -> 12 | G21: {=index('Hitter Stats'!M:M,match($A21,'Hitter Stats'!$A:$A,0))-index('2024'!M:M,match($A21,'2024'!$A:$A,0))} -> 8
A22: =IFERROR(__xludf.DUMMYFUNCTION("""COMPUTED_VALUE"""),606466.0) -> 606466 | B22: {=index('Hitter Stats'!B:B,match(A22,'Hitter Stats'!A:A,0))} -> Ketel Marte | C22: {=index('Hitter Stats'!F:F,match($A22,'Hitter Stats'!$A:$A,0))-index('2024'!F:F,match($A22,'2024'!$A:$A,0))} -> -0.018588573 | D22: {=index('Hitter Stats'!H:H,match($A22,'Hitter Stats'!$A:$A,0))-index('2024'!H:H,match($A22,'2024'!$A:$A,0))} -> 4 | E22: {=index('Hitter Stats'!K:K,match($A22,'Hitter Stats'!$A:$A,0))-index('2024'!K:K,match($A22,'2024'!$A:$A,0))} -> 5 | F22: {=index('Hitter Stats'!L:L,match($A22,'Hitter Stats'!$A:$A,0))-index('2024'!L:L,match($A22,'2024'!$A:$A,0))} -> -6 | G22: {=index('Hitter Stats'!M:M,match($A22,'Hitter Stats'!$A:$A,0))-index('2024'!M:M,match($A22,'2024'!$A:$A,0))} -> -3
A23: =IFERROR(__xludf.DUMMYFUNCTION("""COMPUTED_VALUE"""),656941.0) -> 656941 | B23: {=index('Hitter Stats'!B:B,match(A23,'Hitter Stats'!A:A,0))} -> Kyle Schwarber | C23: {=index('Hitter Stats'!F:F,match($A23,'Hitter Stats'!$A:$A,0))-index('2024'!F:F,match($A23,'2024'!$A:$A,0))} -> 0.013203541 | D23: {=index('Hitter Stats'!H:H,match($A23,'Hitter Stats'!$A:$A,0))-index('2024'!H:H,match($A23,'2024'!$A:$A,0))} -> -11 | E23: {=index('Hitter Stats'!K:K,match($A23,'Hitter Stats'!$A:$A,0))-index('2024'!K:K,match($A23,'2024'!$A:$A,0))} -> -1 | F23: {=index('Hitter Stats'!L:L,match($A23,'Hitter Stats'!$A:$A,0))-index('2024'!L:L,match($A23,'2024'!$A:$A,0))} -> 3 | G23: {=index('Hitter Stats'!M:M,match($A23,'Hitter Stats'!$A:$A,0))-index('2024'!M:M,match($A23,'2024'!$A:$A,0))} -> -4
A24: =IFERROR(__xludf.DUMMYFUNCTION("""COMPUTED_VALUE"""),666018.0) -> 666018 | B24: {=index('Hitter Stats'!B:B,match(A24,'Hitter Stats'!A:A,0))} -> Jonathan Aranda | C24: {=index('Hitter Stats'!F:F,match($A24,'Hitter Stats'!$A:$A,0))-index('2024'!F:F,match($A24,'2024'!$A:$A,0))} -> 0.026588921 | D24: {=index('Hitter Stats'!H:H,match($A24,'Hitter Stats'!$A:$A,0))-index('2024'!H:H,match($A24,'2024'!$A:$A,0))} -> -5 | E24: {=index('Hitter Stats'!K:K,match($A24,'Hitter Stats'!$A:$A,0))-index('2024'!K:K,match($A24,'2024'!$A:$A,0))} -> -12 | F24: {=index('Hitter Stats'!L:L,match($A24,'Hitter Stats'!$A:$A,0))-index('2024'!L:L,match($A24,'2024'!$A:$A,0))} -> 1 | G24: {=index('Hitter Stats'!M:M,match($A24,'Hitter Stats'!$A:$A,0))-index('2024'!M:M,match($A24,'2024'!$A:$A,0))} -> -10
A25: =IFERROR(__xludf.DUMMYFUNCTION("""COMPUTED_VALUE"""),671056.0) -> 671056 | B25: {=index('Hitter Stats'!B:B,match(A25,'Hitter Stats'!A:A,0))} -> Iván Herrera | C25: {=index('Hitter Stats'!F:F,match($A25,'Hitter Stats'!$A:$A,0))-index('2024'!F:F,match($A25,'2024'!$A:$A,0))} -> 0.020028815 | D25: {=index('Hitter Stats'!H:H,match($A25,'Hitter Stats'!$A:$A,0))-index('2024'!H:H,match($A25,'2024'!$A:$A,0))} -> 20 | E25: {=index('Hitter Stats'!K:K,match($A25,'Hitter Stats'!$A:$A,0))-index('2024'!K:K,match($A25,'2024'!$A:$A,0))} -> 5 | F25: {=index('Hitter Stats'!L:L,match($A25,'Hitter Stats'!$A:$A,0))-index('2024'!L:L,match($A25,'2024'!$A:$A,0))} -> -9 | G25: {=index('Hitter Stats'!M:M,match($A25,'Hitter Stats'!$A:$A,0))-index('2024'!M:M,match($A25,'2024'!$A:$A,0))} -> 2
A26: =IFERROR(__xludf.DUMMYFUNCTION("""COMPUTED_VALUE"""),571970.0) -> 571970 | B26: {=index('Hitter Stats'!B:B,match(A26,'Hitter Stats'!A:A,0))} -> Max Muncy | C26: {=index('Hitter Stats'!F:F,match($A26,'Hitter Stats'!$A:$A,0))-index('2024'!F:F,match($A26,'2024'!$A:$A,0))} -> 0.015300497 | D26: {=index('Hitter Stats'!H:H,match($A26,'Hitter Stats'!$A:$A,0))-index('2024'!H:H,match($A26,'2024'!$A:$A,0))} -> 6 | E26: {=index('Hitter Stats'!K:K,match($A26,'Hitter Stats'!$A:$A,0))-index('2024'!K:K,match($A26,'2024'!$A:$A,0))} -> 12 | F26: {=index('Hitter Stats'!L:L,match($A26,'Hitter Stats'!$A:$A,0))-index('2024'!L:L,match($A26,'2024'!$A:$A,0))} -> -2 | G26: {=index('Hitter Stats'!M:M,match($A26,'Hitter Stats'!$A:$A,0))-index('2024'!M:M,match($A26,'2024'!$A:$A,0))} -> 7
A27: =IFERROR(__xludf.DUMMYFUNCTION("""COMPUTED_VALUE"""),677951.0) -> 677951 | B27: {=index('Hitter Stats'!B:B,match(A27,'Hitter Stats'!A:A,0))} -> Bobby Witt Jr. | C27: {=index('Hitter Stats'!F:F,match($A27,'Hitter Stats'!$A:$A,0))-index('2024'!F:F,match($A27,'2024'!$A:$A,0))} -> -0.008316233 | D27: {=index('Hitter Stats'!H:H,match($A27,'Hitter Stats'!$A:$A,0))-index('2024'!H:H,match($A27,'2024'!$A:$A,0))} -> 7 | E27: {=index('Hitter Stats'!K:K,match($A27,'Hitter Stats'!$A:$A,0))-index('2024'!K:K,match($A27,'2024'!$A:$A,0))} -> -9 | F27: {=index('Hitter Stats'!L:L,match($A27,'Hitter Stats'!$A:$A,0))-index('2024'!L:L,match($A27,'2024'!$A:$A,0))} -> -12 | G27: {=index('Hitter Stats'!M:M,match($A27,'Hitter Stats'!$A:$A,0))-index('2024'!M:M,match($A27,'2024'!$A:$A,0))} -> -17
A28: =IFERROR(__xludf.DUMMYFUNCTION("""COMPUTED_VALUE"""),575929.0) -> 575929 | B28: {=index('Hitter Stats'!B:B,match(A28,'Hitter Stats'!A:A,0))} -> Willson Contreras | C28: {=index('Hitter Stats'!F:F,match($A28,'Hitter Stats'!$A:$A,0))-index('2024'!F:F,match($A28,'2024'!$A:$A,0))} -> -0.007183713 | D28: {=index('Hitter Stats'!H:H,match($A28,'Hitter Stats'!$A:$A,0))-index('2024'!H:H,match($A28,'2024'!$A:$A,0))} -> 1 | E28: {=index('Hitter Stats'!K:K,match($A28,'Hitter Stats'!$A:$A,0))-index('2024'!K:K,match($A28,'2024'!$A:$A,0))} -> 3 | F28: {=index('Hitter Stats'!L:L,match($A28,'Hitter Stats'!$A:$A,0))-index('2024'!L:L,match($A28,'2024'!$A:$A,0))} -> 2 | G28: {=index('Hitter Stats'!M:M,match($A28,'Hitter Stats'!$A:$A,0))-index('2024'!M:M,match($A28,'2024'!$A:$A,0))} -> 8
A29: =IFERROR(__xludf.DUMMYFUNCTION("""COMPUTED_VALUE"""),665487.0) -> 665487 | B29: {=index('Hitter Stats'!B:B,match(A29,'Hitter Stats'!A:A,0))} -> Fernando Tatis Jr. | C29: {=index('Hitter Stats'!F:F,match($A29,'Hitter Stats'!$A:$A,0))-index('2024'!F:F,match($A29,'2024'!$A:$A,0))} -> -0.014232739 | D29: {=index('Hitter Stats'!H:H,match($A29,'Hitter Stats'!$A:$A,0))-index('2024'!H:H,match($A29,'2024'!$A:$A,0))} -> 1 | E29: {=index('Hitter Stats'!K:K,match($A29,'Hitter Stats'!$A:$A,0))-index('2024'!K:K,match($A29,'2024'!$A:$A,0))} -> 5 | F29: {=index('Hitter Stats'!L:L,match($A29,'Hitter Stats'!$A:$A,0))-index('2024'!L:L,match($A29,'2024'!$A:$A,0))} -> -16 | G29: {=index('Hitter Stats'!M:M,match($A29,'Hitter Stats'!$A:$A,0))-index('2024'!M:M,match($A29,'2024'!$A:$A,0))} -> -16
A30: =IFERROR(__xludf.DUMMYFUNCTION("""COMPUTED_VALUE"""),667670.0) -> 667670 | B30: {=index('Hitter Stats'!B:B,match(A30,'Hitter Stats'!A:A,0))} -> Brent Rooker | C30: {=index('Hitter Stats'!F:F,match($A30,'Hitter Stats'!$A:$A,0))-index('2024'!F:F,match($A30,'2024'!$A:$A,0))} -> 0.006732989 | D30: {=index('Hitter Stats'!H:H,match($A30,'Hitter Stats'!$A:$A,0))-index('2024'!H:H,match($A30,'2024'!$A:$A,0))} -> 14 | E30: {=index('Hitter Stats'!K:K,match($A30,'Hitter Stats'!$A:$A,0))-index('2024'!K:K,match($A30,'2024'!$A:$A,0))} -> 6 | F30: {=index('Hitter Stats'!L:L,match($A30,'Hitter Stats'!$A:$A,0))-index('2024'!L:L,match($A30,'2024'!$A:$A,0))} -> -26 | G30: {=index('Hitter Stats'!M:M,match($A30,'Hitter Stats'!$A:$A,0))-index('2024'!M:M,match($A30,'2024'!$A:$A,0))} -> -10
A31: =IFERROR(__xludf.DUMMYFUNCTION("""COMPUTED_VALUE"""),666182.0) -> 666182 | B31: {=index('Hitter Stats'!B:B,match(A31,'Hitter Stats'!A:A,0))} -> Bo Bichette | C31: {=index('Hitter Stats'!F:F,match($A31,'Hitter Stats'!$A:$A,0))-index('2024'!F:F,match($A31,'2024'!$A:$A,0))} -> -0.032500578 | D31: {=index('Hitter Stats'!H:H,match($A31,'Hitter Stats'!$A:$A,0))-index('2024'!H:H,match($A31,'2024'!$A:$A,0))} -> -1 | E31: {=index('Hitter Stats'!K:K,match($A31,'Hitter Stats'!$A:$A,0))-index('2024'!K:K,match($A31,'2024'!$A:$A,0))} -> -1 | F31: {=index('Hitter Stats'!L:L,match($A31,'Hitter Stats'!$A:$A,0))-index('2024'!L:L,match($A31,'2024'!$A:$A,0))} -> 19 | G31: {=index('Hitter Stats'!M:M,match($A31,'Hitter Stats'!$A:$A,0))-index('2024'!M:M,match($A31,'2024'!$A:$A,0))} -> 23
A32: =IFERROR(__xludf.DUMMYFUNCTION("""COMPUTED_VALUE"""),682998.0) -> 682998 | B32: {=index('Hitter Stats'!B:B,match(A32,'Hitter Stats'!A:A,0))} -> Corbin Carroll | C32: {=index('Hitter Stats'!F:F,match($A32,'Hitter Stats'!$A:$A,0))-index('2024'!F:F,match($A32,'2024'!$A:$A,0))} -> 0.054026817 | D32: {=index('Hitter Stats'!H:H,match($A32,'Hitter Stats'!$A:$A,0))-index('2024'!H:H,match($A32,'2024'!$A:$A,0))} -> -11 | E32: {=index('Hitter Stats'!K:K,match($A32,'Hitter Stats'!$A:$A,0))-index('2024'!K:K,match($A32,'2024'!$A:$A,0))} -> -16 | F32: {=index('Hitter Stats'!L:L,match($A32,'Hitter Stats'!$A:$A,0))-index('2024'!L:L,match($A32,'2024'!$A:$A,0))} -> 31 | G32: {=index('Hitter Stats'!M:M,match($A32,'Hitter Stats'!$A:$A,0))-index('2024'!M:M,match($A32,'2024'!$A:$A,0))} -> 18
A33: =IFERROR(__xludf.DUMMYFUNCTION("""COMPUTED_VALUE"""),679529.0) -> 679529 | B33: {=index('Hitter Stats'!B:B,match(A33,'Hitter Stats'!A:A,0))} -> Spencer Torkelson | C33: {=index('Hitter Stats'!F:F,match($A33,'Hitter Stats'!$A:$A,0))-index('2024'!F:F,match($A33,'2024'!$A:$A,0))} -> -0.019630059 | D33: {=index('Hitter Stats'!H:H,match($A33,'Hitter Stats'!$A:$A,0))-index('2024'!H:H,match($A33,'2024'!$A:$A,0))} -> 19 | E33: {=index('Hitter Stats'!K:K,match($A33,'Hitter Stats'!$A:$A,0))-index('2024'!K:K,match($A33,'2024'!$A:$A,0))} -> -1 | F33: {=index('Hitter Stats'!L:L,match($A33,'Hitter Stats'!$A:$A,0))-index('2024'!L:L,match($A33,'2024'!$A:$A,0))} -> 20 | G33: {=index('Hitter Stats'!M:M,match($A33,'Hitter Stats'!$A:$A,0))-index('2024'!M:M,match($A33,'2024'!$A:$A,0))} -> 25
A34: =IFERROR(__xludf.DUMMYFUNCTION("""COMPUTED_VALUE"""),596103.0) -> 596103 | B34: {=index('Hitter Stats'!B:B,match(A34,'Hitter Stats'!A:A,0))} -> Austin Slater | C34: {=index('Hitter Stats'!F:F,match($A34,'Hitter Stats'!$A:$A,0))-index('2024'!F:F,match($A34,'2024'!$A:$A,0))} -> 0.029495083 | D34: {=index('Hitter Stats'!H:H,match($A34,'Hitter Stats'!$A:$A,0))-index('2024'!H:H,match($A34,'2024'!$A:$A,0))} -> -5 | E34: {=index('Hitter Stats'!K:K,match($A34,'Hitter Stats'!$A:$A,0))-index('2024'!K:K,match($A34,'2024'!$A:$A,0))} -> 6 | F34: {=index('Hitter Stats'!L:L,match($A34,'Hitter Stats'!$A:$A,0))-index('2024'!L:L,match($A34,'2024'!$A:$A,0))} -> 29 | G34: {=index('Hitter Stats'!M:M,match($A34,'Hitter Stats'!$A:$A,0))-index('2024'!M:M,match($A34,'2024'!$A:$A,0))} -> 25
A35: =IFERROR(__xludf.DUMMYFUNCTION("""COMPUTED_VALUE"""),621566.0) -> 621566 | B35: {=index('Hitter Stats'!B:B,match(A35,'Hitter Stats'!A:A,0))} -> Matt Olson | C35: {=index('Hitter Stats'!F:F,match($A35,'Hitter Stats'!$A:$A,0))-index('2024'!F:F,match($A35,'2024'!$A:$A,0))} -> -0.060673735 | D35: {=index('Hitter Stats'!H:H,match($A35,'Hitter Stats'!$A:$A,0))-index('2024'!H:H,match($A35,'2024'!$A:$A,0))} -> 14 | E35: {=index('Hitter Stats'!K:K,match($A35,'Hitter Stats'!$A:$A,0))-index('2024'!K:K,match($A35,'2024'!$A:$A,0))} -> 4 | F35: {=index('Hitter Stats'!L:L,match($A35,'Hitter Stats'!$A:$A,0))-index('2024'!L:L,match($A35,'2024'!$A:$A,0))} -> 6 | G35: {=index('Hitter Stats'!M:M,match($A35,'Hitter Stats'!$A:$A,0))-index('2024'!M:M,match($A35,'2024'!$A:$A,0))} -> 14
A36: =IFERROR(__xludf.DUMMYFUNCTION("""COMPUTED_VALUE"""),687263.0) -> 687263 | B36: {=index('Hitter Stats'!B:B,match(A36,'Hitter Stats'!A:A,0))} -> Zach Neto | C36: {=index('Hitter Stats'!F:F,match($A36,'Hitter Stats'!$A:$A,0))-index('2024'!F:F,match($A36,'2024'!$A:$A,0))} -> -0.017755833 | D36: {=index('Hitter Stats'!H:H,match($A36,'Hitter Stats'!$A:$A,0))-index('2024'!H:H,match($A36,'2024'!$A:$A,0))} -> 9 | E36: {=index('Hitter Stats'!K:K,match($A36,'Hitter Stats'!$A:$A,0))-index('2024'!K:K,match($A36,'2024'!$A:$A,0))} -> -12 | F36: {=index('Hitter Stats'!L:L,match($A36,'Hitter Stats'!$A:$A,0))-index('2024'!L:L,match($A36,'2024'!$A:$A,0))} -> 18 | G36: {=index('Hitter Stats'!M:M,match($A36,'Hitter Stats'!$A:$A,0))-index('2024'!M:M,match($A36,'2024'!$A:$A,0))} -> 17
A37: =IFERROR(__xludf.DUMMYFUNCTION("""COMPUTED_VALUE"""),663757.0) -> 663757 | B37: {=index('Hitter Stats'!B:B,match(A37,'Hitter Stats'!A:A,0))} -> Trent Grisham | C37: {=index('Hitter Stats'!F:F,match($A37,'Hitter Stats'!$A:$A,0))-index('2024'!F:F,match($A37,'2024'!$A:$A,0))} -> 0.030526452 | D37: {=index('Hitter Stats'!H:H,match($A37,'Hitter Stats'!$A:$A,0))-index('2024'!H:H,match($A37,'2024'!$A:$A,0))} -> -2 | E37: {=index('Hitter Stats'!K:K,match($A37,'Hitter Stats'!$A:$A,0))-index('2024'!K:K,match($A37,'2024'!$A:$A,0))} -> -3 | F37: {=index('Hitter Stats'!L:L,match($A37,'Hitter Stats'!$A:$A,0))-index('2024'!L:L,match($A37,'2024'!$A:$A,0))} -> 27 | G37: {=index('Hitter Stats'!M:M,match($A37,'Hitter Stats'!$A:$A,0))-index('2024'!M:M,match($A37,'2024'!$A:$A,0))} -> 19
A38: =IFERROR(__xludf.DUMMYFUNCTION("""COMPUTED_VALUE"""),669065.0) -> 669065 | B38: {=index('Hitter Stats'!B:B,match(A38,'Hitter Stats'!A:A,0))} -> Kyle Stowers | C38: {=index('Hitter Stats'!F:F,match($A38,'Hitter Stats'!$A:$A,0))-index('2024'!F:F,match($A38,'2024'!$A:$A,0))} -> -0.020521337 | D38: {=index('Hitter Stats'!H:H,match($A38,'Hitter Stats'!$A:$A,0))-index('2024'!H:H,match($A38,'2024'!$A:$A,0))} -> 15 | E38: {=index('Hitter Stats'!K:K,match($A38,'Hitter Stats'!$A:$A,0))-index('2024'!K:K,match($A38,'2024'!$A:$A,0))} -> 1 | F38: {=index('Hitter Stats'!L:L,match($A38,'Hitter Stats'!$A:$A,0))-index('2024'!L:L,match($A38,'2024'!$A:$A,0))} -> 11 | G38: {=index('Hitter Stats'!M:M,match($A38,'Hitter Stats'!$A:$A,0))-index('2024'!M:M,match($A38,'2024'!$A:$A,0))} -> 22
A39: =IFERROR(__xludf.DUMMYFUNCTION("""COMPUTED_VALUE"""),621439.0) -> 621439 | B39: {=index('Hitter Stats'!B:B,match(A39,'Hitter Stats'!A:A,0))} -> Byron Buxton | C39: {=index('Hitter Stats'!F:F,match($A39,'Hitter Stats'!$A:$A,0))-index('2024'!F:F,match($A39,'2024'!$A:$A,0))} -> -0.055438285 | D39: {=index('Hitter Stats'!H:H,match($A39,'Hitter Stats'!$A:$A,0))-index('2024'!H:H,match($A39,'2024'!$A:$A,0))} -> 12 | E39: {=index('Hitter Stats'!K:K,match($A39,'Hitter Stats'!$A:$A,0))-index('2024'!K:K,match($A39,'2024'!$A:$A,0))} -> -2 | F39: {=index('Hitter Stats'!L:L,match($A39,'Hitter Stats'!$A:$A,0))-index('2024'!L:L,match($A39,'2024'!$A:$A,0))} -> 0 | G39: {=index('Hitter Stats'!M:M,match($A39,'Hitter Stats'!$A:$A,0))-index('2024'!M:M,match($A39,'2024'!$A:$A,0))} -> 6
A40: =IFERROR(__xludf.DUMMYFUNCTION("""COMPUTED_VALUE"""),542303.0) -> 542303 | B40: {=index('Hitter Stats'!B:B,match(A40,'Hitter Stats'!A:A,0))} -> Marcell Ozuna | C40: {=index('Hitter Stats'!F:F,match($A40,'Hitter Stats'!$A:$A,0))-index('2024'!F:F,match($A40,'2024'!$A:$A,0))} -> -0.087410177 | D40: {=index('Hitter Stats'!H:H,match($A40,'Hitter Stats'!$A:$A,0))-index('2024'!H:H,match($A40,'2024'!$A:$A,0))} -> 16 | E40: {=index('Hitter Stats'!K:K,match($A40,'Hitter Stats'!$A:$A,0))-index('2024'!K:K,match($A40,'2024'!$A:$A,0))} -> 7 | F40: {=index('Hitter Stats'!L:L,match($A40,'Hitter Stats'!$A:$A,0))-index('2024'!L:L,match($A40,'2024'!$A:$A,0))} -> -29 | G40: {=index('Hitter Stats'!M:M,match($A40,'Hitter Stats'!$A:$A,0))-index('2024'!M:M,match($A40,'2024'!$A:$A,0))} -> -17
...

Sheet Last 400 Pitch Changes
A1: MLBAMID | B1: Hitter | C1: Δ Swing Aggression | D1: Δ Decision Value+ | E1: Δ Contact Ability+ | F1: Δ Power+ | G1: Δ Process+
A2: 665862 | B2: Jazz Chisholm Jr. | C2: 0.039011951 | D2: 0.69167762 | E2: 0.66365742 | F2: 6.1232198 | G2: 2.5237233
A3: 621439 | B3: Byron Buxton | C3: -0.016161588 | D3: 0.71030288 | E3: 0.94314506 | F3: 3.9314705 | G3: 2.2483222
A4: 642715 | B4: Willy Adames | C4: -0.038219045 | D4: 1.222993 | E4: -0.71436617 | F4: 5.8239405 | G4: 1.9167814
A5: 676475 | B5: Alec Burleson | C5: -0.001414363 | D5: 0.051700981 | E5: 0.16027145 | F5: 3.8664828 | G5: 1.7759936
A6: 669065 | B6: Kyle Stowers | C6: -0.009933872 | D6: 0.56192525 | E6: 1.3265479 | F6: 4.046312 | G6: 1.7391794
A7: 608369 | B7: Corey Seager | C7: 0.015870617 | D7: 0.88589325 | E7: -1.3931193 | F7: 5.2523913 | G7: 1.6164642
A8: 521692 | B8: Salvador Perez | C8: -0.034180662 | D8: 1.9126543 | E8: 1.0436733 | F8: 1.2741042 | G8: 1.6057551
A9: 669016 | B9: Brandon Marsh | C9: 0.038510319 | D9: -0.61763878 | E9: 1.3728907 | F9: 3.6792411 | G9: 1.5060284
A10: 592885 | B10: Christian Yelich | C10: 0.000666629 | D10: 1.156905 | E10: -0.31602918 | F10: 3.4673417 | G10: 1.5029329
A11: 683737 | B11: Michael Busch | C11: 0.02921451 | D11: -0.011768446 | E11: 1.5589964 | F11: 2.1439827 | G11: 1.5024463
A12: 666176 | B12: Jo Adell | C12: -0.01667348 | D12: 1.0857937 | E12: 0.22065719 | F12: 3.3293456 | G12: 1.3857485
A13: 672695 | B13: Geraldo Perdomo | C13: -0.002999329 | D13: 0.23407965 | E13: -0.85728978 | F13: 3.9699122 | G13: 1.3106515
... A242: 518692 | B242: Freddie Freeman | C242: 0.003659365 | D242: -1.1915433 | E242: -2.3264577 | F242: -4.9009028 | G242: -2.7973694

Sheet Team Stats
A1: Team | B1: Pitches Faced | C1: Swings | D1: BBE | E1: Swing Aggression | F1: Strikezone Judgement | G1: Decision Value+ | H1: zDV+ | I1: oDV+ | J1: Contact+ | K1: Power+ | L1: Process+ | M1: Performance+
A2: Arizona Diamondbacks | B2: 14385 | C2: 6752 | D2: 2573 | E2: -0.012341183 | F2: 84 | G2: 98 | H2: 99 | I2: 98 | J2: 114 | K2: 104 | L2: 110 | M2: 119
A3: Atlanta Braves | B3: 14180 | C3: 6813 | D3: 2428 | E3: -0.008661524 | F3: 110 | G3: 107 | H3: 112 | I3: 103 | J3: 90 | K3: 108 | L3: 104 | M3: 95
A4: Baltimore Orioles | B4: 13723 | C4: 6640 | D4: 2355 | E4: -0.008337468 | F4: 111 | G4: 109 | H4: 116 | I4: 104 | J4: 88 | K4: 106 | L4: 102 | M4: 99
A5: Boston Red Sox | B5: 14553 | C5: 7128 | D5: 2520 | E5: 0.00619049 | F5: 102 | G5: 87 | H5: 103 | I5: 87 | J5: 98 | K5: 110 | L5: 103 | M5: 112
A6: Chicago Cubs | B6: 14346 | C6: 6873 | D6: 2598 | E6: -0.007487922 | F6: 131 | G6: 119 | H6: 106 | I6: 116 | J6: 97 | K6: 116 | L6: 119 | M6: 121
A7: Chicago White Sox | B7: 13827 | C7: 6547 | D7: 2362 | E7: -0.015368482 | F7: 110 | G7: 114 | H7: 96 | I7: 115 | J7: 83 | K7: 86 | L7: 86 | M7: 72
A8: Cincinnati Reds | B8: 13881 | C8: 6331 | D8: 2375 | E8: -0.031158655 | F8: 89 | G8: 100 | H8: 62 | I8: 112 | J8: 87 | K8: 80 | L8: 78 | M8: 100
A9: Cleveland Guardians | B9: 13635 | C9: 6591 | D9: 2364 | E9: 0.007344467 | F9: 88 | G9: 86 | H9: 119 | I9: 81 | J9: 97 | K9: 76 | L9: 74 | M9: 77
A10: Colorado Rockies | B10: 13388 | C10: 6747 | D10: 2304 | E10: 0.017012118 | F10: 99 | G10: 65 | H10: 91 | I10: 69 | J10: 68 | K10: 93 | L10: 66 | M10: 71
A11: Detroit Tigers | B11: 14289 | C11: 6842 | D11: 2456 | E11: -0.009116739 | F11: 120 | G11: 119 | H11: 121 | I11: 112 | J11: 84 | K11: 123 | L11: 117 | M11: 115
A12: Houston Astros | B12: 13484 | C12: 6567 | D12: 2520 | E12: 0.010246712 | F12: 93 | G12: 85 | H12: 101 | I12: 85 | J12: 108 | K12: 98 | L12: 98 | M12: 112
A13: Kansas City Royals | B13: 13386 | C13: 6495 | D13: 2611 | E13: -0.00201981 | F13: 78 | G13: 80 | H13: 99 | I13: 80 | J13: 132 | K13: 85 | L13: 96 | M13: 82
... A31: Washington Nationals | B31: 13476 | C31: 6376 | D31: 2515 | E31: -0.010798731 | F31: 73 | G31: 83 | H31: 84 | I31: 88 | J31: 109 | K31: 96 | L31: 95 | M31: 89

Sheet Stat Glossary
A1: Stat | B1: Description
A2: Swing Aggression | B2: How much more often a hitter swings at pitches, given the swing likelihoods of the pitches they face.
A3: Strikezone Judgement | B3: The "correctness" of a hitter's swings and takes, using the likelihood of a pitch being a called strike (for swings) or a ball/HBP (for takes). Value is + scale, and League Average is 100.
A4: Decision Value | B4: Value of a hitter's decision to swing or take, minus the value of the alternative. Value is + scale, and League Average is 100.
A5: zDV | B5: Decision Value on pitches in the Strike Zone
A6: oDV | B6: Decision Value on pitches out of the Strike Zone
A7: Contact Ability | B7: A hitter's ability to make contact (foul strike or BIP), above the contact expectation of each pitch. Value is + scale, and League Average is 100.
A8: Power | B8: A hitter's ability to add extra bases to the expectation of the pitches they hit into play. Value is + scale, and League Average is 100.
A9: Hitter Performance | B9: Value added by the hitter (including swing/take decisions), after accounting for pitch quality. Value is + scale, and League Average is 100.
A10: wCON | B10: EXPERIMENTAL: Contact Ability * zDV. A proxy for how much contact a hitter would add over a league average pitch
A11: wPOW | B11: EXPERIMENTAL: Power * zDV: A proxy for how much power a hitter would add over a league average pitch.

Sheet Roster Rate
A1: =IFERROR(__xludf.DUMMYFUNCTION("IMPORTHTML(""https://www.fantasypros.com/mlb/projections/ros-hitters.php"",""table"",1)"),"VBR") -> VBR | B1: =IFERROR(__xludf.DUMMYFUNCTION("""COMPUTED_VALUE"""),"Player") -> Player | C1: =IFERROR(__xludf.DUMMYFUNCTION("""COMPUTED_VALUE"""),"AB") -> AB | D1: =IFERROR(__xludf.DUMMYFUNCTION("""COMPUTED_VALUE"""),"R") -> R | E1: =IFERROR(__xludf.DUMMYFUNCTION("""COMPUTED_VALUE"""),"HR") -> HR | F1: =IFERROR(__xludf.DUMMYFUNCTION("""COMPUTED_VALUE"""),"RBI") -> RBI | G1: =IFERROR(__xludf.DUMMYFUNCTION("""COMPUTED_VALUE"""),"SB") -> SB | H1: =IFERROR(__xludf.DUMMYFUNCTION("""COMPUTED_VALUE"""),"AVG") -> AVG | I1: =IFERROR(__xludf.DUMMYFUNCTION("""COMPUTED_VALUE"""),"OBP") -> OBP | J1: =IFERROR(__xludf.DUMMYFUNCTION("""COMPUTED_VALUE"""),"H") -> H | K1: =IFERROR(__xludf.DUMMYFUNCTION("""COMPUTED_VALUE"""),"2B") -> 2B | L1: =IFERROR(__xludf.DUMMYFUNCTION("""COMPUTED_VALUE"""),"3B") -> 3B | M1: =IFERROR(__xludf.DUMMYFUNCTION("""COMPUTED_VALUE"""),"BB") -> BB | N1: =IFERROR(__xludf.DUMMYFUNCTION("""COMPUTED_VALUE"""),"SO") -> SO | O1: =IFERROR(__xludf.DUMMYFUNCTION("""COMPUTED_VALUE"""),"SLG") -> SLG | P1: =IFERROR(__xludf.DUMMYFUNCTION("""COMPUTED_VALUE"""),"OPS") -> OPS | Q1: =IFERROR(__xludf.DUMMYFUNCTION("""COMPUTED_VALUE"""),"Rost%") -> Rost%
A2: =IFERROR(__xludf.DUMMYFUNCTION("""COMPUTED_VALUE"""),1.0) -> 1 | B2: =IFERROR(__xludf.DUMMYFUNCTION("""COMPUTED_VALUE"""),"Shohei Ohtani (LAD - SP,DH)") -> Shohei Ohtani (LAD - SP,DH) | C2: =IFERROR(__xludf.DUMMYFUNCTION("""COMPUTED_VALUE"""),464.0) -> 464 | D2: =IFERROR(__xludf.DUMMYFUNCTION("""COMPUTED_VALUE"""),102.0) -> 102 | E2: =IFERROR(__xludf.DUMMYFUNCTION("""COMPUTED_VALUE"""),37.0) -> 37 | F2: =IFERROR(__xludf.DUMMYFUNCTION("""COMPUTED_VALUE"""),91.0) -> 91 | G2: =IFERROR(__xludf.DUMMYFUNCTION("""COMPUTED_VALUE"""),19.0) -> 19 | H2: =IFERROR(__xludf.DUMMYFUNCTION("""COMPUTED_VALUE"""),0.28) -> 0.28 | I2: =IFERROR(__xludf.DUMMYFUNCTION("""COMPUTED_VALUE"""),0.401) -> 0.401 | J2: =IFERROR(__xludf.DUMMYFUNCTION("""COMPUTED_VALUE"""),130.0) -> 130 | K2: =IFERROR(__xludf.DUMMYFUNCTION("""COMPUTED_VALUE"""),23.0) -> 23 | L2: =IFERROR(__xludf.DUMMYFUNCTION("""COMPUTED_VALUE"""),4.0) -> 4 | M2: =IFERROR(__xludf.DUMMYFUNCTION("""COMPUTED_VALUE"""),80.0) -> 80 | N2: =IFERROR(__xludf.DUMMYFUNCTION("""COMPUTED_VALUE"""),133.0) -> 133 | O2: =IFERROR(__xludf.DUMMYFUNCTION("""COMPUTED_VALUE"""),0.583) -> 0.583 | P2: =IFERROR(__xludf.DUMMYFUNCTION("""COMPUTED_VALUE"""),0.983) -> 0.983 | Q2: =IFERROR(__xludf.DUMMYFUNCTION("""COMPUTED_VALUE"""),1.0) -> 1 | S2: =IFERROR(__xludf.DUMMYFUNCTION("""COMPUTED_VALUE"""),1.0) -> 1 | T2: =trim(left(B2,find("(",B2)-1)) -> Shohei Ohtani
A3: =IFERROR(__xludf.DUMMYFUNCTION("""COMPUTED_VALUE"""),2.0) -> 2 | B3: =IFERROR(__xludf.DUMMYFUNCTION("""COMPUTED_VALUE"""),"Aaron Judge (NYY - LF,CF,RF,DH)") -> Aaron Judge (NYY - LF,CF,RF,DH) | C3: =IFERROR(__xludf.DUMMYFUNCTION("""COMPUTED_VALUE"""),422.0) -> 422 | D3: =IFERROR(__xludf.DUMMYFUNCTION("""COMPUTED_VALUE"""),91.0) -> 91 | E3: =IFERROR(__xludf.DUMMYFUNCTION("""COMPUTED_VALUE"""),38.0) -> 38 | F3: =IFERROR(__xludf.DUMMYFUNCTION("""COMPUTED_VALUE"""),94.0) -> 94 | G3: =IFERROR(__xludf.DUMMYFUNCTION("""COMPUTED_VALUE"""),9.0) -> 9 | H3: =IFERROR(__xludf.DUMMYFUNCTION("""COMPUTED_VALUE"""),0.285) -> 0.285 | I3: =IFERROR(__xludf.DUMMYFUNCTION("""COMPUTED_VALUE"""),0.437) -> 0.437 | J3: =IFERROR(__xludf.DUMMYFUNCTION("""COMPUTED_VALUE"""),120.0) -> 120 | K3: =IFERROR(__xludf.DUMMYFUNCTION("""COMPUTED_VALUE"""),20.0) -> 20 | L3: =IFERROR(__xludf.DUMMYFUNCTION("""COMPUTED_VALUE"""),1.0) -> 1 | M3: =IFERROR(__xludf.DUMMYFUNCTION("""COMPUTED_VALUE"""),95.0) -> 95 | N3: =IFERROR(__xludf.DUMMYFUNCTION("""COMPUTED_VALUE"""),131.0) -> 131 | O3: =IFERROR(__xludf.DUMMYFUNCTION("""COMPUTED_VALUE"""),0.608) -> 0.608 | P3: =IFERROR(__xludf.DUMMYFUNCTION("""COMPUTED_VALUE"""),1.045) -> 1.045 | Q3: =IFERROR(__xludf.DUMMYFUNCTION("""COMPUTED_VALUE"""),0.99) -> 0.99 | R3: =IFERROR(__xludf.DUMMYFUNCTION("""COMPUTED_VALUE"""),0.99) -> 0.99 | S3: =IFERROR(__xludf.DUMMYFUNCTION("""COMPUTED_VALUE"""),1.0) -> 1 | T3: =trim(left(B3,find("(",B3)-1)) -> Aaron Judge
