Workbook

Sheet Cy Young Rank
A1: Pitcher | B1: Team | C1: IP | D1: ERA | E1: xERA | F1: MLBAMID | G1: Cleaned_IP | H1: League | I1: PLA | J1: Weighted Rate | K1: Runs Saved | L1: PLA Runs Saved | N1: Lg ERA | O1: 4.06 | Q1: Team | R1: League
A2: Trevor Megill | B2: MIL | C2: 47 | D2: 2.4893619 | E2: 3.225335 | F2: 656730 | G2: =int(C2)+(C2-int(C2))*10/3 -> 47 | H2: =IFERROR(__xludf.DUMMYFUNCTION("if(B2=""- - -"",""Trade"",filter(R:R,Q:Q=B2))"),"NL") -> NL | I2: {=index('PLV (min 500)'!F:F,match(F2,'PLV (min 500)'!B:B,0))} -> 1.7158012 | J2: {=(indirect("D2:D"&counta(A:A))+indirect("E2:E"&counta(A:A))+indirect("I2:I"&COUNTA(A:A)))/3} -> 2.4768327 | K2: {=(O1-indirect("J2:J"&counta(A:A)))*indirect("C2:C"&counta(A:A))/9} -> 8.2676515 | L2: {=(O1-indirect("I2:I"&counta(A:A)))*indirect("C2:C"&counta(A:A))/9} -> 12.241927 | N2: Repl ERA | O2: =O1/4.4*5.63 -> 5.1949545 | Q2: MIN | R2: AL | T2: AL CY Leaders (Blend) | W2: NL CY Leaders (Blend)
A3: Tyler Rogers | B3: - - - | C3: 77.1 | D3: 1.9784484 | E3: 2.6673094 | F3: 643511 | G3: =int(C3)+(C3-int(C3))*10/3 -> 77.333333 | H3: =IFERROR(__xludf.DUMMYFUNCTION("if(B3=""- - -"",""Trade"",filter(R:R,Q:Q=B3))"),"Trade") -> Trade | I3: {=index('PLV (min 500)'!F:F,match(F3,'PLV (min 500)'!B:B,0))} -> 1.8713997 | J3: 2.1723858 | K3: 16.170561 | L3: 18.749009 | Q3: BOS | R3: AL | T3: Name | U3: Runs Saved | W3: Name | X3: Runs Saved
A4: Reid Detmers | B4: LAA | C4: 63.2 | D4: 3.9581156 | E4: 3.6015416 | F4: 672282 | G4: =int(C4)+(C4-int(C4))*10/3 -> 63.666667 | H4: =IFERROR(__xludf.DUMMYFUNCTION("if(B4=""- - -"",""Trade"",filter(R:R,Q:Q=B4))"),"AL") -> AL | I4: {=index('PLV (min 500)'!F:F,match(F4,'PLV (min 500)'!B:B,0))} -> 1.9083886 | J4: 3.1560152 | K4: 6.3479818 | L4: 15.109094 | Q4: SDP | R4: NL | T4: =IFERROR(__xludf.DUMMYFUNCTION("sortn(filter({A:A,K:K},H:H=""AL"",not(ISNA(K:K))),5,,2,0)"),"Tarik Skubal") -> Tarik Skubal | U4: =IFERROR(__xludf.DUMMYFUNCTION("""COMPUTED_VALUE"""),34.4984500233132) -> 34.49845 | W4: =IFERROR(__xludf.DUMMYFUNCTION("sortn(filter({A:A,K:K},H:H=""NL"",not(ISNA(K:K))),5,,2,0)"),"Paul Skenes") -> Paul Skenes | X4: =IFERROR(__xludf.DUMMYFUNCTION("""COMPUTED_VALUE"""),34.903760145242614) -> 34.90376
A5: Griffin Jax | B5: - - - | C5: 66 | D5: 4.2272732 | E5: 3.2507001 | F5: 643377 | G5: =int(C5)+(C5-int(C5))*10/3 -> 66 | H5: =IFERROR(__xludf.DUMMYFUNCTION("if(B5=""- - -"",""Trade"",filter(R:R,Q:Q=B5))"),"Trade") -> Trade | I5: {=index('PLV (min 500)'!F:F,match(F5,'PLV (min 500)'!B:B,0))} -> 1.9745295 | J5: 3.1508343 | K5: 6.6672152 | L5: 15.29345 | Q5: KCR | R5: AL | T5: =IFERROR(__xludf.DUMMYFUNCTION("""COMPUTED_VALUE"""),"Garrett Crochet") -> Garrett Crochet | U5: =IFERROR(__xludf.DUMMYFUNCTION("""COMPUTED_VALUE"""),31.129028020669427) -> 31.129028 | W5: =IFERROR(__xludf.DUMMYFUNCTION("""COMPUTED_VALUE"""),"Cristopher Sánchez") -> Cristopher Sánchez | X5: =IFERROR(__xludf.DUMMYFUNCTION("""COMPUTED_VALUE"""),33.33103390183877) -> 33.331034
A6: Randy Rodríguez | B6: SFG | C6: 50.2 | D6: 1.776316 | E6: 2.5568538 | F6: 678495 | G6: =int(C6)+(C6-int(C6))*10/3 -> 50.666667 | H6: =IFERROR(__xludf.DUMMYFUNCTION("if(B6=""- - -"",""Trade"",filter(R:R,Q:Q=B6))"),"NL") -> NL | I6: {=index('PLV (min 500)'!F:F,match(F6,'PLV (min 500)'!B:B,0))} -> 2.0363753 | J6: 2.1231817 | K6: 10.803142 | L6: 11.287329 | Q6: MIL | R6: NL | T6: =IFERROR(__xludf.DUMMYFUNCTION("""COMPUTED_VALUE"""),"Bryan Woo") -> Bryan Woo | U6: =IFERROR(__xludf.DUMMYFUNCTION("""COMPUTED_VALUE"""),25.02131096955754) -> 25.021311 | W6: =IFERROR(__xludf.DUMMYFUNCTION("""COMPUTED_VALUE"""),"Yoshinobu Yamamoto") -> Yoshinobu Yamamoto | X6: =IFERROR(__xludf.DUMMYFUNCTION("""COMPUTED_VALUE"""),28.694739590735324) -> 28.69474
A7: Tanner Scott | B7: LAD | C7: 57 | D7: 4.7368427 | E7: 4.1771184 | F7: 656945 | G7: =int(C7)+(C7-int(C7))*10/3 -> 57 | H7: =IFERROR(__xludf.DUMMYFUNCTION("if(B7=""- - -"",""Trade"",filter(R:R,Q:Q=B7))"),"NL") -> NL | I7: {=index('PLV (min 500)'!F:F,match(F7,'PLV (min 500)'!B:B,0))} -> 2.1292881 | J7: 3.6810831 | K7: 2.3998072 | L7: 12.227842 | Q7: CHC | R7: NL | T7: =IFERROR(__xludf.DUMMYFUNCTION("""COMPUTED_VALUE"""),"Nathan Eovaldi") -> Nathan Eovaldi | U7: =IFERROR(__xludf.DUMMYFUNCTION("""COMPUTED_VALUE"""),22.944523322296547) -> 22.944523 | W7: =IFERROR(__xludf.DUMMYFUNCTION("""COMPUTED_VALUE"""),"Zack Wheeler") -> Zack Wheeler | X7: =IFERROR(__xludf.DUMMYFUNCTION("""COMPUTED_VALUE"""),25.066626136302208) -> 25.066626
A8: Janson Junk | B8: MIA | C8: 110 | D8: 4.1727275 | E8: 4.436317 | F8: 676083 | G8: =int(C8)+(C8-int(C8))*10/3 -> 110 | H8: =IFERROR(__xludf.DUMMYFUNCTION("if(B8=""- - -"",""Trade"",filter(R:R,Q:Q=B8))"),"NL") -> NL | I8: {=index('PLV (min 500)'!F:F,match(F8,'PLV (min 500)'!B:B,0))} -> 2.1874231 | J8: 3.5988225 | K8: 5.6366135 | L8: 22.887051 | Q8: SEA | R8: AL | T8: =IFERROR(__xludf.DUMMYFUNCTION("""COMPUTED_VALUE"""),"Max Fried") -> Max Fried | U8: =IFERROR(__xludf.DUMMYFUNCTION("""COMPUTED_VALUE"""),22.393979989078076) -> 22.39398 | W8: =IFERROR(__xludf.DUMMYFUNCTION("""COMPUTED_VALUE"""),"Logan Webb") -> Logan Webb | X8: =IFERROR(__xludf.DUMMYFUNCTION("""COMPUTED_VALUE"""),22.4462049195448) -> 22.446205
A9: Steven Okert | B9: HOU | C9: 71.2 | D9: 3.0139542 | E9: 2.6324468 | F9: 595345 | G9: =int(C9)+(C9-int(C9))*10/3 -> 71.666667 | H9: =IFERROR(__xludf.DUMMYFUNCTION("if(B9=""- - -"",""Trade"",filter(R:R,Q:Q=B9))"),"AL") -> AL | I9: {=index('PLV (min 500)'!F:F,match(F9,'PLV (min 500)'!B:B,0))} -> 2.1921442 | J9: 2.6128484 | K9: 11.448577 | L9: 14.776815 | Q9: TOR | R9: AL
A10: Aroldis Chapman | B10: BOS | C10: 61.1 | D10: 1.1739131 | E10: 2.0602816 | F10: 547973 | G10: =int(C10)+(C10-int(C10))*10/3 -> 61.333333 | H10: =IFERROR(__xludf.DUMMYFUNCTION("if(B10=""- - -"",""Trade"",filter(R:R,Q:Q=B10))"),"AL") -> AL | I10: {=index('PLV (min 500)'!F:F,match(F10,'PLV (min 500)'!B:B,0))} -> 2.202632 | J10: 1.8122756 | K10: 15.259551 | L10: 12.609465 | Q10: HOU | R10: AL | T10: AL CY Leaders (PLA-Only) | W10: NL CY Leaders (PLA-Only)
A11: Cristopher Sánchez | B11: PHI | C11: 202 | D11: 2.4950495 | E11: 3.0239149 | F11: 650911 | G11: =int(C11)+(C11-int(C11))*10/3 -> 202 | H11: =IFERROR(__xludf.DUMMYFUNCTION("if(B11=""- - -"",""Trade"",filter(R:R,Q:Q=B11))"),"NL") -> NL | I11: {=index('PLV (min 500)'!F:F,match(F11,'PLV (min 500)'!B:B,0))} -> 2.2058974 | J11: 2.5749539 | K11: 33.331034 | L11: 41.614303 | Q11: ATL | R11: NL | T11: Name | U11: Runs Saved | W11: Name | X11: Runs Saved
A12: Louis Varland | B12: - - - | C12: 72.2 | D12: 2.9724775 | E12: 3.9992833 | F12: 686973 | G12: =int(C12)+(C12-int(C12))*10/3 -> 72.666667 | H12: =IFERROR(__xludf.DUMMYFUNCTION("if(B12=""- - -"",""Trade"",filter(R:R,Q:Q=B12))"),"Trade") -> Trade | I12: {=index('PLV (min 500)'!F:F,match(F12,'PLV (min 500)'!B:B,0))} -> 2.2121899 | J12: 3.0613169 | K12: 8.0116579 | L12: 14.823543 | Q12: PHI | R12: NL | T12: =IFERROR(__xludf.DUMMYFUNCTION("sortn(filter({A:A,L:L},H:H=""AL"",not(ISNA(L:L))),5,,2,0)"),"Tarik Skubal") -> Tarik Skubal | U12: =IFERROR(__xludf.DUMMYFUNCTION("""COMPUTED_VALUE"""),34.16875430871739) -> 34.168754 | W12: =IFERROR(__xludf.DUMMYFUNCTION("sortn(filter({A:A,L:L},H:H=""NL"",not(ISNA(L:L))),5,,2,0)"),"Cristopher Sánchez") -> Cristopher Sánchez | X12: =IFERROR(__xludf.DUMMYFUNCTION("""COMPUTED_VALUE"""),41.61430344640524) -> 41.614303
A13: Andrew Kittredge | B13: - - - | C13: 53 | D13: 3.3962268 | E13: 2.7779116 | F13: 552640 | G13: =int(C13)+(C13-int(C13))*10/3 -> 53 | H13: =IFERROR(__xludf.DUMMYFUNCTION("if(B13=""- - -"",""Trade"",filter(R:R,Q:Q=B13))"),"Trade") -> Trade | I13: {=index('PLV (min 500)'!F:F,match(F13,'PLV (min 500)'!B:B,0))} -> 2.2675138 | J13: 2.8138841 | K13: 7.3382382 | L13: 10.555752 | Q13: SFG | R13: NL | T13: =IFERROR(__xludf.DUMMYFUNCTION("""COMPUTED_VALUE"""),"Garrett Crochet") -> Garrett Crochet | U13: =IFERROR(__xludf.DUMMYFUNCTION("""COMPUTED_VALUE"""),32.909136854941636) -> 32.909137 | W13: =IFERROR(__xludf.DUMMYFUNCTION("""COMPUTED_VALUE"""),"Logan Webb") -> Logan Webb | X13: =IFERROR(__xludf.DUMMYFUNCTION("""COMPUTED_VALUE"""),36.99172800163443) -> 36.991728
A14: Adrian Morejon | B14: SDP | C14: 73.2 | D14: 2.0769236 | E14: 2.6323855 | F14: 670970 | G14: =int(C14)+(C14-int(C14))*10/3 -> 73.666667 | H14: =IFERROR(__xludf.DUMMYFUNCTION("if(B14=""- - -"",""Trade"",filter(R:R,Q:Q=B14))"),"NL") -> NL | I14: {=index('PLV (min 500)'!F:F,match(F14,'PLV (min 500)'!B:B,0))} -> 2.2851079 | J14: 2.3314723 | K14: 14.058692 | L14: 14.435789 | Q14: LAA | R14: AL | T14: =IFERROR(__xludf.DUMMYFUNCTION("""COMPUTED_VALUE"""),"Jacob deGrom") -> Jacob deGrom | U14: =IFERROR(__xludf.DUMMYFUNCTION("""COMPUTED_VALUE"""),32.83847469532234) -> 32.838475 | W14: =IFERROR(__xludf.DUMMYFUNCTION("""COMPUTED_VALUE"""),"Paul Skenes") -> Paul Skenes | X14: =IFERROR(__xludf.DUMMYFUNCTION("""COMPUTED_VALUE"""),31.88381208052784) -> 31.883812
A15: Max Kranick | B15: NYM | C15: 37 | D15: 3.6486494 | E15: 4.534288 | F15: 668820 | G15: =int(C15)+(C15-int(C15))*10/3 -> 37 | H15: =IFERROR(__xludf.DUMMYFUNCTION("if(B15=""- - -"",""Trade"",filter(R:R,Q:Q=B15))"),"NL") -> NL | I15: {=index('PLV (min 500)'!F:F,match(F15,'PLV (min 500)'!B:B,0))} -> 2.3236142 | J15: 3.5021839 | K15: 2.2932442 | L15: 7.1384751 | Q15: ATH | R15: AL | T15: =IFERROR(__xludf.DUMMYFUNCTION("""COMPUTED_VALUE"""),"Bryan Woo") -> Bryan Woo | U15: =IFERROR(__xludf.DUMMYFUNCTION("""COMPUTED_VALUE"""),31.433001956517064) -> 31.433002 | W15: =IFERROR(__xludf.DUMMYFUNCTION("""COMPUTED_VALUE"""),"Yoshinobu Yamamoto") -> Yoshinobu Yamamoto | X15: =IFERROR(__xludf.DUMMYFUNCTION("""COMPUTED_VALUE"""),30.104188827183748) -> 30.104189
A16: Gabe Speier | B16: SEA | C16: 62 | D16: 2.612904 | E16: 2.4875135 | F16: 642100 | G16: =int(C16)+(C16-int(C16))*10/3 -> 62 | H16: =IFERROR(__xludf.DUMMYFUNCTION("if(B16=""- - -"",""Trade"",filter(R:R,Q:Q=B16))"),"AL") -> AL | I16: {=index('PLV (min 500)'!F:F,match(F16,'PLV (min 500)'!B:B,0))} -> 2.3431374 | J16: 2.481185 | K16: 10.876281 | L16: 11.827276 | Q16: TBR | R16: AL | T16: =IFERROR(__xludf.DUMMYFUNCTION("""COMPUTED_VALUE"""),"Framber Valdez") -> Framber Valdez | U16: =IFERROR(__xludf.DUMMYFUNCTION("""COMPUTED_VALUE"""),29.86511333569784) -> 29.865113 | W16: =IFERROR(__xludf.DUMMYFUNCTION("""COMPUTED_VALUE"""),"Sonny Gray") -> Sonny Gray | X16: =IFERROR(__xludf.DUMMYFUNCTION("""COMPUTED_VALUE"""),29.75378191844148) -> 29.753782
A17: Tyler Mahle | B17: TEX | C17: 86.2 | D17: 2.1807693 | E17: 4.2263154 | F17: 641816 | G17: =int(C17)+(C17-int(C17))*10/3 -> 86.666667 | H17: =IFERROR(__xludf.DUMMYFUNCTION("if(B17=""- - -"",""Trade"",filter(R:R,Q:Q=B17))"),"AL") -> AL | I17: {=index('PLV (min 500)'!F:F,match(F17,'PLV (min 500)'!B:B,0))} -> 2.3431385 | J17: 2.9167411 | K17: 10.94988 | L17: 16.443718 | Q17: LAD | R17: NL
A18: Jacob deGrom | B18: TEX | C18: 172.2 | D18: 2.9710426 | E18: 3.3567821 | F18: 594798 | G18: =int(C18)+(C18-int(C18))*10/3 -> 172.66667 | H18: =IFERROR(__xludf.DUMMYFUNCTION("if(B18=""- - -"",""Trade"",filter(R:R,Q:Q=B18))"),"AL") -> AL | I18: {=index('PLV (min 500)'!F:F,match(F18,'PLV (min 500)'!B:B,0))} -> 2.3437034 | J18: 2.8905094 | K18: 22.376254 | L18: 32.838475 | Q18: NYY | R18: AL
A19: Josh Hader | B19: HOU | C19: 52.2 | D19: 2.050633 | E19: 1.9958071 | F19: 623352 | G19: =int(C19)+(C19-int(C19))*10/3 -> 52.666667 | H19: =IFERROR(__xludf.DUMMYFUNCTION("if(B19=""- - -"",""Trade"",filter(R:R,Q:Q=B19))"),"AL") -> AL | I19: {=index('PLV (min 500)'!F:F,match(F19,'PLV (min 500)'!B:B,0))} -> 2.3685456 | J19: 2.1383286 | K19: 11.145694 | L19: 9.8104355 | Q19: PIT | R19: NL
A20: Tyler Phillips | B20: MIA | C20: 77.2 | D20: 2.7811162 | E20: 3.6445599 | F20: 663969 | G20: =int(C20)+(C20-int(C20))*10/3 -> 77.666667 | H20: =IFERROR(__xludf.DUMMYFUNCTION("if(B20=""- - -"",""Trade"",filter(R:R,Q:Q=B20))"),"NL") -> NL | I20: {=index('PLV (min 500)'!F:F,match(F20,'PLV (min 500)'!B:B,0))} -> 2.3758108 | J20: 2.933829 | K20: 9.660045 | L20: 14.446601 | Q20: DET | R20: AL
A21: Brandon Walter | B21: HOU | C21: 53.2 | D21: 3.3540374 | E21: 3.2531604 | F21: 687888 | G21: =int(C21)+(C21-int(C21))*10/3 -> 53.666667 | H21: =IFERROR(__xludf.DUMMYFUNCTION("if(B21=""- - -"",""Trade"",filter(R:R,Q:Q=B21))"),"AL") -> AL | I21: {=index('PLV (min 500)'!F:F,match(F21,'PLV (min 500)'!B:B,0))} -> 2.4029452 | J21: 3.003381 | K21: 6.2457924 | L21: 9.7950353 | Q21: ARI | R21: NL
A22: Spencer Schwellenbach | B22: ATL | C22: 110.2 | D22: 3.0903615 | E22: 3.5590851 | F22: 680885 | G22: =int(C22)+(C22-int(C22))*10/3 -> 110.66667 | H22: =IFERROR(__xludf.DUMMYFUNCTION("if(B22=""- - -"",""Trade"",filter(R:R,Q:Q=B22))"),"NL") -> NL | I22: {=index('PLV (min 500)'!F:F,match(F22,'PLV (min 500)'!B:B,0))} -> 2.4034586 | J22: 3.0176351 | K22: 12.763179 | L22: 20.283429 | Q22: CIN | R22: NL
A23: Shota Imanaga | B23: CHC | C23: 144.2 | D23: 3.7327192 | E23: 4.0625737 | F23: 684007 | G23: =int(C23)+(C23-int(C23))*10/3 -> 144.66667 | H23: =IFERROR(__xludf.DUMMYFUNCTION("if(B23=""- - -"",""Trade"",filter(R:R,Q:Q=B23))"),"NL") -> NL | I23: {=index('PLV (min 500)'!F:F,match(F23,'PLV (min 500)'!B:B,0))} -> 2.4042784 | J23: 3.3998571 | K23: 10.576957 | L23: 26.52834 | Q23: BAL | R23: AL
A24: Tim Hill | B24: NYY | C24: 67 | D24: 3.0895529 | E24: 3.3920004 | F24: 657612 | G24: =int(C24)+(C24-int(C24))*10/3 -> 67 | H24: =IFERROR(__xludf.DUMMYFUNCTION("if(B24=""- - -"",""Trade"",filter(R:R,Q:Q=B24))"),"AL") -> AL | I24: {=index('PLV (min 500)'!F:F,match(F24,'PLV (min 500)'!B:B,0))} -> 2.4095871 | J24: 2.9637135 | K24: 8.1612441 | L24: 12.286407 | Q24: CLE | R24: AL
A25: Caleb Thielbar | B25: CHC | C25: 58 | D25: 2.6379317 | E25: 2.4802919 | F25: 573204 | G25: =int(C25)+(C25-int(C25))*10/3 -> 58 | H25: =IFERROR(__xludf.DUMMYFUNCTION("if(B25=""- - -"",""Trade"",filter(R:R,Q:Q=B25))"),"NL") -> NL | I25: {=index('PLV (min 500)'!F:F,match(F25,'PLV (min 500)'!B:B,0))} -> 2.4237968 | J25: 2.5140068 | K25: 9.9630671 | L25: 10.54442 | Q25: STL | R25: NL
A26: Hunter Greene | B26: CIN | C26: 107.2 | D26: 2.758514 | E26: 3.0333519 | F26: 668881 | G26: =int(C26)+(C26-int(C26))*10/3 -> 107.66667 | H26: =IFERROR(__xludf.DUMMYFUNCTION("if(B26=""- - -"",""Trade"",filter(R:R,Q:Q=B26))"),"NL") -> NL | I26: {=index('PLV (min 500)'!F:F,match(F26,'PLV (min 500)'!B:B,0))} -> 2.431789 | J26: 2.7412183 | K26: 15.708155 | L26: 19.393802 | Q26: NYM | R26: NL
A27: Chris Martin | B27: TEX | C27: 42.1 | D27: 2.9763786 | E27: 3.7744814 | F27: 455119 | G27: =int(C27)+(C27-int(C27))*10/3 -> 42.333333 | H27: =IFERROR(__xludf.DUMMYFUNCTION("if(B27=""- - -"",""Trade"",filter(R:R,Q:Q=B27))"),"AL") -> AL | I27: {=index('PLV (min 500)'!F:F,match(F27,'PLV (min 500)'!B:B,0))} -> 2.4394058 | J27: 3.0634219 | K27: 4.6617708 | L27: 7.5807796 | Q27: COL | R27: NL
A28: Bryan King | B28: HOU | C28: 68 | D28: 2.7794124 | E28: 3.0591769 | F28: 687911 | G28: =int(C28)+(C28-int(C28))*10/3 -> 68 | H28: =IFERROR(__xludf.DUMMYFUNCTION("if(B28=""- - -"",""Trade"",filter(R:R,Q:Q=B28))"),"AL") -> AL | I28: {=index('PLV (min 500)'!F:F,match(F28,'PLV (min 500)'!B:B,0))} -> 2.4429499 | J28: 2.7605131 | K28: 9.8183455 | L28: 12.217712 | Q28: TEX | R28: AL
A29: Logan Webb | B29: SFG | C29: 207 | D29: 3.2173913 | E29: 3.5831788 | F29: 657277 | G29: =int(C29)+(C29-int(C29))*10/3 -> 207 | H29: =IFERROR(__xludf.DUMMYFUNCTION("if(B29=""- - -"",""Trade"",filter(R:R,Q:Q=B29))"),"NL") -> NL | I29: {=index('PLV (min 500)'!F:F,match(F29,'PLV (min 500)'!B:B,0))} -> 2.451664 | J29: 3.084078 | K29: 22.446205 | L29: 36.991728 | Q29: CHW | R29: AL
A30: Zack Wheeler | B30: PHI | C30: 149.2 | D30: 2.7060135 | E30: 2.4815738 | F30: 554430 | G30: =int(C30)+(C30-int(C30))*10/3 -> 149.66667 | H30: =IFERROR(__xludf.DUMMYFUNCTION("if(B30=""- - -"",""Trade"",filter(R:R,Q:Q=B30))"),"NL") -> NL | I30: {=index('PLV (min 500)'!F:F,match(F30,'PLV (min 500)'!B:B,0))} -> 2.4562269 | J30: 2.5479381 | K30: 25.066626 | L30: 26.586994 | Q30: WSN | R30: NL
A31: Robert Suarez | B31: SDP | C31: 69.2 | D31: 2.971292 | E31: 3.6462501 | F31: 663158 | G31: =int(C31)+(C31-int(C31))*10/3 -> 69.666667 | H31: =IFERROR(__xludf.DUMMYFUNCTION("if(B31=""- - -"",""Trade"",filter(R:R,Q:Q=B31))"),"NL") -> NL | I31: {=index('PLV (min 500)'!F:F,match(F31,'PLV (min 500)'!B:B,0))} -> 2.4752977 | J31: 3.0309466 | K31: 7.9122773 | L31: 12.1846 | Q31: MIA | R31: NL
A32: Tyler Holton | B32: DET | C32: 78.2 | D32: 3.6610176 | E32: 3.7857884 | F32: 663947 | G32: =int(C32)+(C32-int(C32))*10/3 -> 78.666667 | H32: =IFERROR(__xludf.DUMMYFUNCTION("if(B32=""- - -"",""Trade"",filter(R:R,Q:Q=B32))"),"AL") -> AL | I32: {=index('PLV (min 500)'!F:F,match(F32,'PLV (min 500)'!B:B,0))} -> 2.4756014 | J32: 3.3074691 | K32: 6.538657 | L32: 13.766663
A33: Steven Matz | B33: - - - | C33: 76.2 | D33: 3.0521745 | E33: 3.3764229 | F33: 571927 | G33: =int(C33)+(C33-int(C33))*10/3 -> 76.666667 | H33: =IFERROR(__xludf.DUMMYFUNCTION("if(B33=""- - -"",""Trade"",filter(R:R,Q:Q=B33))"),"Trade") -> Trade | I33: {=index('PLV (min 500)'!F:F,match(F33,'PLV (min 500)'!B:B,0))} -> 2.4801599 | J33: 2.9695858 | K33: 9.2321737 | L33: 13.37598
A34: Tarik Skubal | B34: DET | C34: 195.1 | D34: 2.2116042 | E34: 2.7103468 | F34: 669373 | G34: =int(C34)+(C34-int(C34))*10/3 -> 195.33333 | H34: =IFERROR(__xludf.DUMMYFUNCTION("if(B34=""- - -"",""Trade"",filter(R:R,Q:Q=B34))"),"AL") -> AL | I34: {=index('PLV (min 500)'!F:F,match(F34,'PLV (min 500)'!B:B,0))} -> 2.4837889 | J34: 2.46858 | K34: 34.49845 | L34: 34.168754
A35: Yoshinobu Yamamoto | B35: LAD | C35: 173.2 | D35: 2.4875241 | E35: 2.7235829 | F35: 808967 | G35: =int(C35)+(C35-int(C35))*10/3 -> 173.66667 | H35: =IFERROR(__xludf.DUMMYFUNCTION("if(B35=""- - -"",""Trade"",filter(R:R,Q:Q=B35))"),"NL") -> NL | I35: {=index('PLV (min 500)'!F:F,match(F35,'PLV (min 500)'!B:B,0))} -> 2.4956946 | J35: 2.5689339 | K35: 28.69474 | L35: 30.104189
A36: Jose A. Ferrer | B36: WSN | C36: 76.1 | D36: 4.4803501 | E36: 3.5606082 | F36: 678606 | G36: =int(C36)+(C36-int(C36))*10/3 -> 76.333333 | H36: =IFERROR(__xludf.DUMMYFUNCTION("if(B36=""- - -"",""Trade"",filter(R:R,Q:Q=B36))"),"NL") -> NL | I36: {=index('PLV (min 500)'!F:F,match(F36,'PLV (min 500)'!B:B,0))} -> 2.5010553 | J36: 3.5140045 | K36: 4.616695 | L36: 13.181744
A37: Jacob Webb | B37: TEX | C37: 66 | D37: 3.0000003 | E37: 3.2290655 | F37: 657097 | G37: =int(C37)+(C37-int(C37))*10/3 -> 66 | H37: =IFERROR(__xludf.DUMMYFUNCTION("if(B37=""- - -"",""Trade"",filter(R:R,Q:Q=B37))"),"AL") -> AL | I37: {=index('PLV (min 500)'!F:F,match(F37,'PLV (min 500)'!B:B,0))} -> 2.5216032 | J37: 2.9168897 | K37: 8.382809 | L37: 11.281576
A38: Paul Skenes | B38: PIT | C38: 187.2 | D38: 1.9662523 | E38: 2.6524271 | F38: 694973 | G38: =int(C38)+(C38-int(C38))*10/3 -> 187.66667 | H38: =IFERROR(__xludf.DUMMYFUNCTION("if(B38=""- - -"",""Trade"",filter(R:R,Q:Q=B38))"),"NL") -> NL | I38: {=index('PLV (min 500)'!F:F,match(F38,'PLV (min 500)'!B:B,0))} -> 2.5271244 | J38: 2.3819346 | K38: 34.90376 | L38: 31.883812
A39: Anthony Bender | B39: MIA | C39: 50 | D39: 2.1600003 | E39: 3.5544879 | F39: 669622 | G39: =int(C39)+(C39-int(C39))*10/3 -> 50 | H39: =IFERROR(__xludf.DUMMYFUNCTION("if(B39=""- - -"",""Trade"",filter(R:R,Q:Q=B39))"),"NL") -> NL | I39: {=index('PLV (min 500)'!F:F,match(F39,'PLV (min 500)'!B:B,0))} -> 2.528743 | J39: 2.7477437 | K39: 7.2903126 | L39: 8.5069836
A40: Bryan Woo | B40: SEA | C40: 186.2 | D40: 2.9410716 | E40: 3.070022 | F40: 693433 | G40: =int(C40)+(C40-int(C40))*10/3 -> 186.66667 | H40: =IFERROR(__xludf.DUMMYFUNCTION("if(B40=""- - -"",""Trade"",filter(R:R,Q:Q=B40))"),"AL") -> AL | I40: {=index('PLV (min 500)'!F:F,match(F40,'PLV (min 500)'!B:B,0))} -> 2.540682 | J40: 2.8505918 | K40: 25.021311 | L40: 31.433002
...

Sheet PLV (min 500)
A1: Pitcher | B1: MLBAMID | C1: Pitches | D1: IP | E1: PLV | F1: PLA | G1: Quality Pitch | H1: Average Pitch | I1: Bad Pitch | J1: QP-BP | K1: Hit Luck
A2: Trevor Megill | B2: 656730 | C2: 737 | D2: =sumif('PLA Sheet'!C:C,B2,'PLA Sheet'!H:H) -> 47 | E2: 5.5514421 | F2: =sumif('PLA Sheet'!C:C,B2,'PLA Sheet'!J:J)/D2*9 -> 1.7158012 | G2: 0.60108548 | H2: 0.13975577 | I2: 0.25915875 | J2: =G2-I2 -> 0.34192673 | K2: 0.026851477
A3: Reid Detmers | B3: 672282 | C3: 1020 | D3: =sumif('PLA Sheet'!C:C,B3,'PLA Sheet'!H:H) -> 63.666667 | E3: 5.5238184 | F3: =sumif('PLA Sheet'!C:C,B3,'PLA Sheet'!J:J)/D3*9 -> 1.9083886 | G3: 0.58235294 | H3: 0.13921569 | I3: 0.27843137 | J3: =G3-I3 -> 0.30392157 | K3: -7.7116497
A4: Griffin Jax | B4: 643377 | C4: 1049 | D4: =sumif('PLA Sheet'!C:C,B4,'PLA Sheet'!H:H) -> 66 | E4: 5.4576651 | F4: =sumif('PLA Sheet'!C:C,B4,'PLA Sheet'!J:J)/D4*9 -> 1.9745295 | G4: 0.53670162 | H4: 0.20591039 | I4: 0.25738799 | J4: =G4-I4 -> 0.27931363 | K4: -3.4514801
A5: Tanner Scott | B5: 656945 | C5: 893 | D5: =sumif('PLA Sheet'!C:C,B5,'PLA Sheet'!H:H) -> 57 | E5: 5.4445539 | F5: =sumif('PLA Sheet'!C:C,B5,'PLA Sheet'!J:J)/D5*9 -> 2.1292881 | G5: 0.56326988 | H5: 0.16797312 | I5: 0.268757 | J5: =G5-I5 -> 0.29451288 | K5: -9.8789835
A6: Randy Rodríguez | B6: 678495 | C6: 780 | D6: =sumif('PLA Sheet'!C:C,B6,'PLA Sheet'!H:H) -> 50.666667 | E6: 5.4348132 | F6: =sumif('PLA Sheet'!C:C,B6,'PLA Sheet'!J:J)/D6*9 -> 2.0363753 | G6: 0.55128205 | H6: 0.11282051 | I6: 0.33589744 | J6: =G6-I6 -> 0.21538462 | K6: -2.4292653
A7: Aroldis Chapman | B7: 547973 | C7: 881 | D7: =sumif('PLA Sheet'!C:C,B7,'PLA Sheet'!H:H) -> 61.333333 | E7: 5.3745096 | F7: =sumif('PLA Sheet'!C:C,B7,'PLA Sheet'!J:J)/D7*9 -> 2.202632 | G7: 0.55505108 | H7: 0.16118048 | I7: 0.28376844 | J7: =G7-I7 -> 0.27128263 | K7: 12.552375
A8: Devin Williams | B8: 642207 | C8: 1087 | D8: =sumif('PLA Sheet'!C:C,B8,'PLA Sheet'!H:H) -> 62 | E8: 5.3575811 | F8: =sumif('PLA Sheet'!C:C,B8,'PLA Sheet'!J:J)/D8*9 -> 2.6608426 | G8: 0.54829807 | H8: 0.15731371 | I8: 0.29438822 | J8: =G8-I8 -> 0.25390984 | K8: 3.8162202
A9: Janson Junk | B9: 676083 | C9: 1558 | D9: =sumif('PLA Sheet'!C:C,B9,'PLA Sheet'!H:H) -> 110 | E9: 5.3540381 | F9: =sumif('PLA Sheet'!C:C,B9,'PLA Sheet'!J:J)/D9*9 -> 2.1874231 | G9: 0.5224647 | H9: 0.19768934 | I9: 0.27984596 | J9: =G9-I9 -> 0.24261874 | K9: -16.067187
A10: Josh Hader | B10: 623352 | C10: 823 | D10: =sumif('PLA Sheet'!C:C,B10,'PLA Sheet'!H:H) -> 52.666667 | E10: 5.3476922 | F10: =sumif('PLA Sheet'!C:C,B10,'PLA Sheet'!J:J)/D10*9 -> 2.3685456 | G10: 0.54799514 | H10: 0.14823815 | I10: 0.30376671 | J10: =G10-I10 -> 0.24422843 | K10: 4.6397033
A11: Hunter Greene | B11: 668881 | C11: 1692 | D11: =sumif('PLA Sheet'!C:C,B11,'PLA Sheet'!H:H) -> 107.66667 | E11: 5.3405949 | F11: =sumif('PLA Sheet'!C:C,B11,'PLA Sheet'!J:J)/D11*9 -> 2.431789 | G11: 0.53605201 | H11: 0.17434988 | I11: 0.28959811 | J11: =G11-I11 -> 0.2464539 | K11: 17.872929
A12: Tyler Rogers | B12: 643511 | C12: 946 | D12: =sumif('PLA Sheet'!C:C,B12,'PLA Sheet'!H:H) -> 77.333333 | E12: 5.3372516 | F12: =sumif('PLA Sheet'!C:C,B12,'PLA Sheet'!J:J)/D12*9 -> 1.8713997 | G12: 0.54122622 | H12: 0.18921776 | I12: 0.26955602 | J12: =G12-I12 -> 0.27167019 | K12: 3.5067686
A13: Tyler Mahle | B13: 641816 | C13: 1346 | D13: =sumif('PLA Sheet'!C:C,B13,'PLA Sheet'!H:H) -> 86.666667 | E13: 5.3364491 | F13: =sumif('PLA Sheet'!C:C,B13,'PLA Sheet'!J:J)/D13*9 -> 2.3431385 | G13: 0.53046062 | H13: 0.17459138 | I13: 0.29494799 | J13: =G13-I13 -> 0.23551263 | K13: 6.6930349
... A472: Roki Sasaki | B472: 808963 | C472: 601 | D472: =sumif('PLA Sheet'!C:C,B472,'PLA Sheet'!H:H) -> 36.333333 | E472: 4.6873089 | F472: =sumif('PLA Sheet'!C:C,B472,'PLA Sheet'!J:J)/D472*9 -> 4.5268596 | G472: 0.39434276 | H472: 0.19467554 | I472: 0.4109817 | J472: =G472-I472 -> -0.016638935 | K472: 6.425786

Sheet Pitch Type (min 250)
A1: Pitcher | B1: MLBAMID | C1: Pitch | D1: Pitches | E1: IP Proxy | F1: PLV | G1: PLA | H1: Quality Pitch | I1: Average Pitch | J1: Bad Pitch | K1: QP-BP | L1: Hit Luck | M1: PLA Runs Saved
A2: Michael Wacha | B2: 608379 | C2: CH | D2: 654 | E2: =IFERROR(__xludf.DUMMYFUNCTION("sum(filter('PLA Sheet'!H:H,'PLA Sheet'!C:C=B2,'PLA Sheet'!D:D=C2))"),43.896107150000006) -> 43.896107 | F2: 5.7637381 | G2: =IFERROR(__xludf.DUMMYFUNCTION("sum(filter('PLA Sheet'!J:J,'PLA Sheet'!C:C=B2,'PLA Sheet'!D:D=C2))/E2*9"),1.0113278347963937) -> 1.0113278 | H2: 0.63914373 | I2: 0.14831804 | J2: 0.21253823 | K2: =H2-J2 -> 0.4266055 | L2: 6.7720383 | M2: =('Cy Young Rank'!O$1-G2)*E2/9 -> 14.869427
A3: Jake Bird | B3: 656234 | C3: SL | D3: 304 | E3: =IFERROR(__xludf.DUMMYFUNCTION("sum(filter('PLA Sheet'!H:H,'PLA Sheet'!C:C=B3,'PLA Sheet'!D:D=C3))"),17.924068264) -> 17.924068 | F3: 5.7611047 | G3: =IFERROR(__xludf.DUMMYFUNCTION("sum(filter('PLA Sheet'!J:J,'PLA Sheet'!C:C=B3,'PLA Sheet'!D:D=C3))/E3*9"),1.1194844666097061) -> 1.1194845 | H3: 0.65789474 | I3: 0.11842105 | J3: 0.22368421 | K3: =H3-J3 -> 0.43421053 | L3: 1.1010824 | M3: =('Cy Young Rank'!O$1-G3)*E3/9 -> 5.8562224 | O3: MVPitches (PLA)
A4: Devin Williams | B4: 642207 | C4: CH | D4: 568 | E4: =IFERROR(__xludf.DUMMYFUNCTION("sum(filter('PLA Sheet'!H:H,'PLA Sheet'!C:C=B4,'PLA Sheet'!D:D=C4))"),32.56396396) -> 32.563964 | F4: 5.7221676 | G4: =IFERROR(__xludf.DUMMYFUNCTION("sum(filter('PLA Sheet'!J:J,'PLA Sheet'!C:C=B4,'PLA Sheet'!D:D=C4))/E4*9"),1.2834065610481655) -> 1.2834066 | H4: 0.61091549 | I4: 0.16725352 | J4: 0.22183099 | K4: =H4-J4 -> 0.38908451 | L4: 3.1311552 | M4: =('Cy Young Rank'!O$1-G4)*E4/9 -> 10.046321 | O4: Name | P4: Type | Q4: Runs Saved
A5: Josh Hader | B5: 623352 | C5: SI | D5: 445 | E5: =IFERROR(__xludf.DUMMYFUNCTION("sum(filter('PLA Sheet'!H:H,'PLA Sheet'!C:C=B5,'PLA Sheet'!D:D=C5))"),28.51221434) -> 28.512214 | F5: 5.674214 | G5: =IFERROR(__xludf.DUMMYFUNCTION("sum(filter('PLA Sheet'!J:J,'PLA Sheet'!C:C=B5,'PLA Sheet'!D:D=C5))/E5*9"),1.5126174167221837) -> 1.5126174 | H5: 0.64494382 | I5: 0.096629213 | J5: 0.25842697 | K5: =H5-J5 -> 0.38651685 | L5: -0.39444621 | M5: =('Cy Young Rank'!O$1-G5)*E5/9 -> 8.0701687 | O5: =IFERROR(__xludf.DUMMYFUNCTION("sortn({A2:A951,C2:C951,M2:M951},10,,3,0)"),"Ryne Nelson") -> Ryne Nelson | P5: =IFERROR(__xludf.DUMMYFUNCTION("""COMPUTED_VALUE"""),"FF") -> FF | Q5: =IFERROR(__xludf.DUMMYFUNCTION("""COMPUTED_VALUE"""),21.287068777777776) -> 21.287069
A6: Ronny Henriquez | B6: 678692 | C6: FF | D6: 330 | E6: =IFERROR(__xludf.DUMMYFUNCTION("sum(filter('PLA Sheet'!H:H,'PLA Sheet'!C:C=B6,'PLA Sheet'!D:D=C6))"),21.704407948) -> 21.704408 | F6: 5.6624448 | G6: =IFERROR(__xludf.DUMMYFUNCTION("sum(filter('PLA Sheet'!J:J,'PLA Sheet'!C:C=B6,'PLA Sheet'!D:D=C6))/E6*9"),1.7650117935389258) -> 1.7650118 | H6: 0.66666667 | I6: 0.078787879 | J6: 0.25454545 | K6: =H6-J6 -> 0.41212121 | L6: -4.6597412 | M6: =('Cy Young Rank'!O$1-G6)*E6/9 -> 5.5345956 | O6: =IFERROR(__xludf.DUMMYFUNCTION("""COMPUTED_VALUE"""),"Joe Ryan") -> Joe Ryan | P6: =IFERROR(__xludf.DUMMYFUNCTION("""COMPUTED_VALUE"""),"FF") -> FF | Q6: =IFERROR(__xludf.DUMMYFUNCTION("""COMPUTED_VALUE"""),19.137827742822218) -> 19.137828
A7: George Kirby | B7: 669923 | C7: SL | D7: 545 | E7: =IFERROR(__xludf.DUMMYFUNCTION("sum(filter('PLA Sheet'!H:H,'PLA Sheet'!C:C=B7,'PLA Sheet'!D:D=C7))"),34.489932890000006) -> 34.489933 | F7: 5.6579634 | G7: =IFERROR(__xludf.DUMMYFUNCTION("sum(filter('PLA Sheet'!J:J,'PLA Sheet'!C:C=B7,'PLA Sheet'!D:D=C7))/E7*9"),1.4028031644569543) -> 1.4028032 | H7: 0.62018349 | I7: 0.16146789 | J7: 0.21834862 | K7: =H7-J7 -> 0.40183486 | L7: -3.2785633 | M7: =('Cy Young Rank'!O$1-G7)*E7/9 -> 10.182949 | O7: =IFERROR(__xludf.DUMMYFUNCTION("""COMPUTED_VALUE"""),"Freddy Peralta") -> Freddy Peralta | P7: =IFERROR(__xludf.DUMMYFUNCTION("""COMPUTED_VALUE"""),"FF") -> FF | Q7: =IFERROR(__xludf.DUMMYFUNCTION("""COMPUTED_VALUE"""),18.29252361211111) -> 18.292524
A8: Paul Skenes | B8: 694973 | C8: FS | D8: 356 | E8: =IFERROR(__xludf.DUMMYFUNCTION("sum(filter('PLA Sheet'!H:H,'PLA Sheet'!C:C=B8,'PLA Sheet'!D:D=C8))"),23.106106109) -> 23.106106 | F8: 5.631468 | G8: =IFERROR(__xludf.DUMMYFUNCTION("sum(filter('PLA Sheet'!J:J,'PLA Sheet'!C:C=B8,'PLA Sheet'!D:D=C8))/E8*9"),1.485011876866388) -> 1.4850119 | H8: 0.60393258 | I8: 0.12921348 | J8: 0.26685393 | K8: =H8-J8 -> 0.33707865 | L8: -3.0914999 | M8: =('Cy Young Rank'!O$1-G8)*E8/9 -> 6.6108832 | O8: =IFERROR(__xludf.DUMMYFUNCTION("""COMPUTED_VALUE"""),"Cristopher Sánchez") -> Cristopher Sánchez | P8: =IFERROR(__xludf.DUMMYFUNCTION("""COMPUTED_VALUE"""),"SI") -> SI | Q8: =IFERROR(__xludf.DUMMYFUNCTION("""COMPUTED_VALUE"""),17.856531945199997) -> 17.856532
A9: Griffin Jax | B9: 643377 | C9: ST | D9: 455 | E9: =IFERROR(__xludf.DUMMYFUNCTION("sum(filter('PLA Sheet'!H:H,'PLA Sheet'!C:C=B9,'PLA Sheet'!D:D=C9))"),28.79560036) -> 28.7956 | F9: 5.6250136 | G9: =IFERROR(__xludf.DUMMYFUNCTION("sum(filter('PLA Sheet'!J:J,'PLA Sheet'!C:C=B9,'PLA Sheet'!D:D=C9))/E9*9"),1.3189361751511681) -> 1.3189362 | H9: 0.57582418 | I9: 0.2 | J9: 0.22417582 | K9: =H9-J9 -> 0.35164835 | L9: -1.5036579 | M9: =('Cy Young Rank'!O$1-G9)*E9/9 -> 8.7700643 | O9: =IFERROR(__xludf.DUMMYFUNCTION("""COMPUTED_VALUE"""),"Cristopher Sánchez") -> Cristopher Sánchez | P9: =IFERROR(__xludf.DUMMYFUNCTION("""COMPUTED_VALUE"""),"CH") -> CH | Q9: =IFERROR(__xludf.DUMMYFUNCTION("""COMPUTED_VALUE"""),17.247619798164436) -> 17.24762
A10: Calvin Faucher | B10: 676534 | C10: FC | D10: 380 | E10: =IFERROR(__xludf.DUMMYFUNCTION("sum(filter('PLA Sheet'!H:H,'PLA Sheet'!C:C=B10,'PLA Sheet'!D:D=C10))"),22.267235924) -> 22.267236 | F10: 5.624555 | G10: =IFERROR(__xludf.DUMMYFUNCTION("sum(filter('PLA Sheet'!J:J,'PLA Sheet'!C:C=B10,'PLA Sheet'!D:D=C10))/E10*9"),1.633214922773726) -> 1.6332149 | H10: 0.62894737 | I10: 0.097368421 | J10: 0.27368421 | K10: =H10-J10 -> 0.35526316 | L10: 0.76488801 | M10: =('Cy Young Rank'!O$1-G10)*E10/9 -> 6.0041995 | O10: =IFERROR(__xludf.DUMMYFUNCTION("""COMPUTED_VALUE"""),"Kevin Gausman") -> Kevin Gausman | P10: =IFERROR(__xludf.DUMMYFUNCTION("""COMPUTED_VALUE"""),"FF") -> FF | Q10: =IFERROR(__xludf.DUMMYFUNCTION("""COMPUTED_VALUE"""),16.96203055613332) -> 16.962031
A11: Reid Detmers | B11: 672282 | C11: FF | D11: 456 | E11: =IFERROR(__xludf.DUMMYFUNCTION("sum(filter('PLA Sheet'!H:H,'PLA Sheet'!C:C=B11,'PLA Sheet'!D:D=C11))"),28.100338567999998) -> 28.100339 | F11: 5.6194888 | G11: =IFERROR(__xludf.DUMMYFUNCTION("sum(filter('PLA Sheet'!J:J,'PLA Sheet'!C:C=B11,'PLA Sheet'!D:D=C11))/E11*9"),1.7448506138582696) -> 1.7448506 | H11: 0.625 | I11: 0.10087719 | J11: 0.27412281 | K11: =H11-J11 -> 0.35087719 | L11: -5.5556855 | M11: =('Cy Young Rank'!O$1-G11)*E11/9 -> 7.228498 | O11: =IFERROR(__xludf.DUMMYFUNCTION("""COMPUTED_VALUE"""),"Jacob deGrom") -> Jacob deGrom | P11: =IFERROR(__xludf.DUMMYFUNCTION("""COMPUTED_VALUE"""),"FF") -> FF | Q11: =IFERROR(__xludf.DUMMYFUNCTION("""COMPUTED_VALUE"""),16.927679593111105) -> 16.92768
A12: Tanner Scott | B12: 656945 | C12: FF | D12: 473 | E12: =IFERROR(__xludf.DUMMYFUNCTION("sum(filter('PLA Sheet'!H:H,'PLA Sheet'!C:C=B12,'PLA Sheet'!D:D=C12))"),30.032930843) -> 30.032931 | F12: 5.6172776 | G12: =IFERROR(__xludf.DUMMYFUNCTION("sum(filter('PLA Sheet'!J:J,'PLA Sheet'!C:C=B12,'PLA Sheet'!D:D=C12))/E12*9"),1.7439320948660435) -> 1.7439321 | H12: 0.60465116 | I12: 0.13530655 | J12: 0.26004228 | K12: =H12-J12 -> 0.34460888 | L12: -10.095218 | M12: =('Cy Young Rank'!O$1-G12)*E12/9 -> 7.7287008 | O12: =IFERROR(__xludf.DUMMYFUNCTION("""COMPUTED_VALUE"""),"Shota Imanaga") -> Shota Imanaga | P12: =IFERROR(__xludf.DUMMYFUNCTION("""COMPUTED_VALUE"""),"FF") -> FF | Q12: =IFERROR(__xludf.DUMMYFUNCTION("""COMPUTED_VALUE"""),16.75101416786666) -> 16.751014
A13: Tomoyuki Sugano | B13: 608372 | C13: ST | D13: 488 | E13: =IFERROR(__xludf.DUMMYFUNCTION("sum(filter('PLA Sheet'!H:H,'PLA Sheet'!C:C=B13,'PLA Sheet'!D:D=C13))"),31.155165694) -> 31.155166 | F13: 5.6109605 | G13: =IFERROR(__xludf.DUMMYFUNCTION("sum(filter('PLA Sheet'!J:J,'PLA Sheet'!C:C=B13,'PLA Sheet'!D:D=C13))/E13*9"),1.5042991733799638) -> 1.5042992 | H13: 0.54508197 | I13: 0.21721312 | J13: 0.23770492 | K13: =H13-J13 -> 0.30737705 | L13: -12.276505 | M13: =('Cy Young Rank'!O$1-G13)*E13/9 -> 8.8470314 | O13: =IFERROR(__xludf.DUMMYFUNCTION("""COMPUTED_VALUE"""),"Robbie Ray") -> Robbie Ray | P13: =IFERROR(__xludf.DUMMYFUNCTION("""COMPUTED_VALUE"""),"FF") -> FF | Q13: =IFERROR(__xludf.DUMMYFUNCTION("""COMPUTED_VALUE"""),15.595909921688884) -> 15.59591
A14: Jhoan Duran | B14: 661395 | C14: FS | D14: 420 | E14: =IFERROR(__xludf.DUMMYFUNCTION("sum(filter('PLA Sheet'!H:H,'PLA Sheet'!C:C=B14,'PLA Sheet'!D:D=C14))"),27.98695247) -> 27.986952 | F14: 5.60951 | G14: =IFERROR(__xludf.DUMMYFUNCTION("sum(filter('PLA Sheet'!J:J,'PLA Sheet'!C:C=B14,'PLA Sheet'!D:D=C14))/E14*9"),1.614302452131188) -> 1.6143025 | H14: 0.60238095 | I14: 0.14761905 | J14: 0.25 | K14: =H14-J14 -> 0.35238095 | L14: 2.5202932 | M14: =('Cy Young Rank'!O$1-G14)*E14/9 -> 7.6052912 | O14: =IFERROR(__xludf.DUMMYFUNCTION("""COMPUTED_VALUE"""),"Yusei Kikuchi") -> Yusei Kikuchi | P14: =IFERROR(__xludf.DUMMYFUNCTION("""COMPUTED_VALUE"""),"SL") -> SL | Q14: =IFERROR(__xludf.DUMMYFUNCTION("""COMPUTED_VALUE"""),15.49968114722222) -> 15.499681
A15: Hunter Greene | B15: 668881 | C15: FF | D15: 913 | E15: =IFERROR(__xludf.DUMMYFUNCTION("sum(filter('PLA Sheet'!H:H,'PLA Sheet'!C:C=B15,'PLA Sheet'!D:D=C15))"),58.32971014) -> 58.32971 | F15: 5.6069734 | G15: =IFERROR(__xludf.DUMMYFUNCTION("sum(filter('PLA Sheet'!J:J,'PLA Sheet'!C:C=B15,'PLA Sheet'!D:D=C15))/E15*9"),1.7614801745695765) -> 1.7614802 | H15: 0.62322015 | I15: 0.14019715 | J15: 0.23658269 | K15: =H15-J15 -> 0.38663746 | L15: 6.8217226 | M15: =('Cy Young Rank'!O$1-G15)*E15/9 -> 14.896888
A16: Dylan Lee | B16: 669276 | C16: FF | D16: 334 | E16: =IFERROR(__xludf.DUMMYFUNCTION("sum(filter('PLA Sheet'!H:H,'PLA Sheet'!C:C=B16,'PLA Sheet'!D:D=C16))"),21.33091349) -> 21.330913 | F16: 5.5997561 | G16: =IFERROR(__xludf.DUMMYFUNCTION("sum(filter('PLA Sheet'!J:J,'PLA Sheet'!C:C=B16,'PLA Sheet'!D:D=C16))/E16*9"),1.7523979466479007) -> 1.7523979 | H16: 0.65568862 | I16: 0.080838323 | J16: 0.26347305 | K16: =H16-J16 -> 0.39221557 | L16: -5.3339484 | M16: =('Cy Young Rank'!O$1-G16)*E16/9 -> 5.4692511
A17: Jesús Luzardo | B17: 666200 | C17: SI | D17: 292 | E17: =IFERROR(__xludf.DUMMYFUNCTION("sum(filter('PLA Sheet'!H:H,'PLA Sheet'!C:C=B17,'PLA Sheet'!D:D=C17))"),18.287421175) -> 18.287421 | F17: 5.5994779 | G17: =IFERROR(__xludf.DUMMYFUNCTION("sum(filter('PLA Sheet'!J:J,'PLA Sheet'!C:C=B17,'PLA Sheet'!D:D=C17))/E17*9"),1.7097007664887447) -> 1.7097008 | H17: 0.63356164 | I17: 0.17123288 | J17: 0.19520548 | K17: =H17-J17 -> 0.43835617 | L17: -4.8974937 | M17: =('Cy Young Rank'!O$1-G17)*E17/9 -> 4.7756569
A18: Joe Ryan | B18: 657746 | C18: FF | D18: 1398 | E18: =IFERROR(__xludf.DUMMYFUNCTION("sum(filter('PLA Sheet'!H:H,'PLA Sheet'!C:C=B18,'PLA Sheet'!D:D=C18))"),87.48837209) -> 87.488372 | F18: 5.5963059 | G18: =IFERROR(__xludf.DUMMYFUNCTION("sum(filter('PLA Sheet'!J:J,'PLA Sheet'!C:C=B18,'PLA Sheet'!D:D=C18))/E18*9"),2.091276093373702) -> 2.0912761 | H18: 0.61802575 | I18: 0.14091559 | J18: 0.24105866 | K18: =H18-J18 -> 0.3769671 | L18: 3.4122471 | M18: =('Cy Young Rank'!O$1-G18)*E18/9 -> 19.137828
A19: Sonny Gray | B19: 543243 | C19: ST | D19: 513 | E19: =IFERROR(__xludf.DUMMYFUNCTION("sum(filter('PLA Sheet'!H:H,'PLA Sheet'!C:C=B19,'PLA Sheet'!D:D=C19))"),35.05571919) -> 35.055719 | F19: 5.5886847 | G19: =IFERROR(__xludf.DUMMYFUNCTION("sum(filter('PLA Sheet'!J:J,'PLA Sheet'!C:C=B19,'PLA Sheet'!D:D=C19))/E19*9"),1.3364911940920874) -> 1.3364912 | H19: 0.54580897 | I19: 0.22612086 | J19: 0.22807018 | K19: =H19-J19 -> 0.31773879 | L19: -6.6967812 | M19: =('Cy Young Rank'!O$1-G19)*E19/9 -> 10.608284
A20: Ranger Suárez | B20: 624133 | C20: FC | D20: 412 | E20: =IFERROR(__xludf.DUMMYFUNCTION("sum(filter('PLA Sheet'!H:H,'PLA Sheet'!C:C=B20,'PLA Sheet'!D:D=C20))"),27.322908092) -> 27.322908 | F20: 5.5854908 | G20: =IFERROR(__xludf.DUMMYFUNCTION("sum(filter('PLA Sheet'!J:J,'PLA Sheet'!C:C=B20,'PLA Sheet'!D:D=C20))/E20*9"),1.6400665276592772) -> 1.6400665 | H20: 0.59466019 | I20: 0.16504854 | J20: 0.24029126 | K20: =H20-J20 -> 0.35436893 | L20: 0.79789489 | M20: =('Cy Young Rank'!O$1-G20)*E20/9 -> 7.3466244
A21: Jeremiah Estrada | B21: 669093 | C21: FF | D21: 679 | E21: =IFERROR(__xludf.DUMMYFUNCTION("sum(filter('PLA Sheet'!H:H,'PLA Sheet'!C:C=B21,'PLA Sheet'!D:D=C21))"),41.461165050000005) -> 41.461165 | F21: 5.5852048 | G21: =IFERROR(__xludf.DUMMYFUNCTION("sum(filter('PLA Sheet'!J:J,'PLA Sheet'!C:C=B21,'PLA Sheet'!D:D=C21))/E21*9"),1.755370065270271) -> 1.7553701 | H21: 0.64064801 | I21: 0.086892489 | J21: 0.2724595 | K21: =H21-J21 -> 0.36818851 | L21: -13.010745 | M21: =('Cy Young Rank'!O$1-G21)*E21/9 -> 10.61696
A22: Reid Detmers | B22: 672282 | C22: SL | D22: 321 | E22: =IFERROR(__xludf.DUMMYFUNCTION("sum(filter('PLA Sheet'!H:H,'PLA Sheet'!C:C=B22,'PLA Sheet'!D:D=C22))"),19.870113877999998) -> 19.870114 | F22: 5.5826865 | G22: =IFERROR(__xludf.DUMMYFUNCTION("sum(filter('PLA Sheet'!J:J,'PLA Sheet'!C:C=B22,'PLA Sheet'!D:D=C22))/E22*9"),1.612307468225976) -> 1.6123075 | H22: 0.55451713 | I22: 0.21183801 | J22: 0.23364486 | K22: =H22-J22 -> 0.32087227 | L22: -0.64479987 | M22: =('Cy Young Rank'!O$1-G22)*E22/9 -> 5.4039921
A23: Yoshinobu Yamamoto | B23: 808967 | C23: FC | D23: 296 | E23: =IFERROR(__xludf.DUMMYFUNCTION("sum(filter('PLA Sheet'!H:H,'PLA Sheet'!C:C=B23,'PLA Sheet'!D:D=C23))"),19.12326638) -> 19.123266 | F23: 5.5812392 | G23: =IFERROR(__xludf.DUMMYFUNCTION("sum(filter('PLA Sheet'!J:J,'PLA Sheet'!C:C=B23,'PLA Sheet'!D:D=C23))/E23*9"),1.670951466399016) -> 1.6709515 | H23: 0.56418919 | I23: 0.19594595 | J23: 0.23986487 | K23: =H23-J23 -> 0.32432432 | L23: 4.1398204 | M23: =('Cy Young Rank'!O$1-G23)*E23/9 -> 5.0762679
A24: Trevor Megill | B24: 656730 | C24: CU | D24: 292 | E24: =IFERROR(__xludf.DUMMYFUNCTION("sum(filter('PLA Sheet'!H:H,'PLA Sheet'!C:C=B24,'PLA Sheet'!D:D=C24))"),18.5) -> 18.5 | F24: 5.5732745 | G24: =IFERROR(__xludf.DUMMYFUNCTION("sum(filter('PLA Sheet'!J:J,'PLA Sheet'!C:C=B24,'PLA Sheet'!D:D=C24))/E24*9"),1.5837397297297298) -> 1.5837397 | H24: 0.55821918 | I24: 0.18835616 | J24: 0.25342466 | K24: =H24-J24 -> 0.30479452 | L24: 6.4717005 | M24: =('Cy Young Rank'!O$1-G24)*E24/9 -> 5.0900906
A25: Orion Kerkering | B25: 689147 | C25: ST | D25: 507 | E25: =IFERROR(__xludf.DUMMYFUNCTION("sum(filter('PLA Sheet'!H:H,'PLA Sheet'!C:C=B25,'PLA Sheet'!D:D=C25))"),28.79776329) -> 28.797763 | F25: 5.5633646 | G25: =IFERROR(__xludf.DUMMYFUNCTION("sum(filter('PLA Sheet'!J:J,'PLA Sheet'!C:C=B25,'PLA Sheet'!D:D=C25))/E25*9"),1.8022362180476137) -> 1.8022362 | H25: 0.56410256 | I25: 0.20315582 | J25: 0.23274162 | K25: =H25-J25 -> 0.33136095 | L25: -5.5448353 | M25: =('Cy Young Rank'!O$1-G25)*E25/9 -> 7.224283
A26: JP Sears | B26: 676664 | C26: ST | D26: 611 | E26: =IFERROR(__xludf.DUMMYFUNCTION("sum(filter('PLA Sheet'!H:H,'PLA Sheet'!C:C=B26,'PLA Sheet'!D:D=C26))"),36.468300934) -> 36.468301 | F26: 5.5605444 | G26: =IFERROR(__xludf.DUMMYFUNCTION("sum(filter('PLA Sheet'!J:J,'PLA Sheet'!C:C=B26,'PLA Sheet'!D:D=C26))/E26*9"),1.8235261664740767) -> 1.8235262 | H26: 0.60392799 | I26: 0.11620295 | J26: 0.27986907 | K26: =H26-J26 -> 0.32405892 | L26: 1.3616425 | M26: =('Cy Young Rank'!O$1-G26)*E26/9 -> 9.0622668
A27: Andrew Kittredge | B27: 552640 | C27: SL | D27: 399 | E27: =IFERROR(__xludf.DUMMYFUNCTION("sum(filter('PLA Sheet'!H:H,'PLA Sheet'!C:C=B27,'PLA Sheet'!D:D=C27))"),28.01822917) -> 28.018229 | F27: 5.5539778 | G27: =IFERROR(__xludf.DUMMYFUNCTION("sum(filter('PLA Sheet'!J:J,'PLA Sheet'!C:C=B27,'PLA Sheet'!D:D=C27))/E27*9"),1.5160706532260833) -> 1.5160707 | H27: 0.55388471 | I27: 0.23809524 | J27: 0.20802005 | K27: =H27-J27 -> 0.34586466 | L27: 6.8914195 | M27: =('Cy Young Rank'!O$1-G27)*E27/9 -> 7.9195995
A28: Jacob Lopez | B28: 682052 | C28: SL | D28: 497 | E28: =IFERROR(__xludf.DUMMYFUNCTION("sum(filter('PLA Sheet'!H:H,'PLA Sheet'!C:C=B28,'PLA Sheet'!D:D=C28))"),28.328728728999998) -> 28.328729 | F28: 5.5538868 | G28: =IFERROR(__xludf.DUMMYFUNCTION("sum(filter('PLA Sheet'!J:J,'PLA Sheet'!C:C=B28,'PLA Sheet'!D:D=C28))/E28*9"),1.7500848511160878) -> 1.7500849 | H28: 0.5694165 | I28: 0.20724346 | J28: 0.22334004 | K28: =H28-J28 -> 0.34607646 | L28: -0.71880278 | M28: =('Cy Young Rank'!O$1-G28)*E28/9 -> 7.2707733
A29: Yusei Kikuchi | B29: 579328 | C29: SL | D29: 1082 | E29: =IFERROR(__xludf.DUMMYFUNCTION("sum(filter('PLA Sheet'!H:H,'PLA Sheet'!C:C=B29,'PLA Sheet'!D:D=C29))"),64.28763875) -> 64.287639 | F29: 5.5486575 | G29: =IFERROR(__xludf.DUMMYFUNCTION("sum(filter('PLA Sheet'!J:J,'PLA Sheet'!C:C=B29,'PLA Sheet'!D:D=C29))/E29*9"),1.890109597469078) -> 1.8901096 | H29: 0.59334566 | I29: 0.15804066 | J29: 0.24861368 | K29: =H29-J29 -> 0.34473198 | L29: -2.4631072 | M29: =('Cy Young Rank'!O$1-G29)*E29/9 -> 15.499681
A30: Janson Junk | B30: 676083 | C30: SL | D30: 449 | E30: =IFERROR(__xludf.DUMMYFUNCTION("sum(filter('PLA Sheet'!H:H,'PLA Sheet'!C:C=B30,'PLA Sheet'!D:D=C30))"),31.87422934) -> 31.874229 | F30: 5.5439806 | G30: =IFERROR(__xludf.DUMMYFUNCTION("sum(filter('PLA Sheet'!J:J,'PLA Sheet'!C:C=B30,'PLA Sheet'!D:D=C30))/E30*9"),1.6410252760012298) -> 1.6410253 | H30: 0.55233853 | I30: 0.20489978 | J30: 0.24276169 | K30: =H30-J30 -> 0.30957684 | L30: -0.83771678 | M30: =('Cy Young Rank'!O$1-G30)*E30/9 -> 8.566995
A31: Trevor Megill | B31: 656730 | C31: FF | D31: 445 | E31: =IFERROR(__xludf.DUMMYFUNCTION("sum(filter('PLA Sheet'!H:H,'PLA Sheet'!C:C=B31,'PLA Sheet'!D:D=C31))"),28.5) -> 28.5 | F31: 5.5371162 | G31: =IFERROR(__xludf.DUMMYFUNCTION("sum(filter('PLA Sheet'!J:J,'PLA Sheet'!C:C=B31,'PLA Sheet'!D:D=C31))/E31*9"),1.8015252631578946) -> 1.8015253 | H31: 0.62921348 | I31: 0.10786517 | J31: 0.26292135 | K31: =H31-J31 -> 0.36629214 | L31: -6.444849 | M31: =('Cy Young Rank'!O$1-G31)*E31/9 -> 7.1518367
A32: Max Meyer | B32: 676974 | C32: SL | D32: 343 | E32: =IFERROR(__xludf.DUMMYFUNCTION("sum(filter('PLA Sheet'!H:H,'PLA Sheet'!C:C=B32,'PLA Sheet'!D:D=C32))"),22.343920439999998) -> 22.34392 | F32: 5.5349243 | G32: =IFERROR(__xludf.DUMMYFUNCTION("sum(filter('PLA Sheet'!J:J,'PLA Sheet'!C:C=B32,'PLA Sheet'!D:D=C32))/E32*9"),1.7564043474547926) -> 1.7564043 | H32: 0.51603499 | I32: 0.2361516 | J32: 0.24781341 | K32: =H32-J32 -> 0.26822157 | L32: -1.6127556 | M32: =('Cy Young Rank'!O$1-G32)*E32/9 -> 5.7190398
A33: Colton Gordon | B33: 676467 | C33: ST | D33: 397 | E33: =IFERROR(__xludf.DUMMYFUNCTION("sum(filter('PLA Sheet'!H:H,'PLA Sheet'!C:C=B33,'PLA Sheet'!D:D=C33))"),24.537560305) -> 24.53756 | F33: 5.5226388 | G33: =IFERROR(__xludf.DUMMYFUNCTION("sum(filter('PLA Sheet'!J:J,'PLA Sheet'!C:C=B33,'PLA Sheet'!D:D=C33))/E33*9"),1.7501902579633821) -> 1.7501903 | H33: 0.53652393 | I33: 0.19395466 | J33: 0.26952141 | K33: =H33-J33 -> 0.26700252 | L33: -2.7535007 | M33: =('Cy Young Rank'!O$1-G33)*E33/9 -> 6.2974551
A34: Jacob Latz | B34: 656641 | C34: FF | D34: 668 | E34: =IFERROR(__xludf.DUMMYFUNCTION("sum(filter('PLA Sheet'!H:H,'PLA Sheet'!C:C=B34,'PLA Sheet'!D:D=C34))"),42.27785783) -> 42.277858 | F34: 5.5201435 | G34: =IFERROR(__xludf.DUMMYFUNCTION("sum(filter('PLA Sheet'!J:J,'PLA Sheet'!C:C=B34,'PLA Sheet'!D:D=C34))/E34*9"),1.9266427671791997) -> 1.9266428 | H34: 0.61227545 | I34: 0.092814371 | J34: 0.29491018 | K34: =H34-J34 -> 0.31736527 | L34: -3.5865385 | M34: =('Cy Young Rank'!O$1-G34)*E34/9 -> 10.02153
A35: Steven Wilson | B35: 621051 | C35: ST | D35: 553 | E35: =IFERROR(__xludf.DUMMYFUNCTION("sum(filter('PLA Sheet'!H:H,'PLA Sheet'!C:C=B35,'PLA Sheet'!D:D=C35))"),32.268309376000005) -> 32.268309 | F35: 5.5097779 | G35: =IFERROR(__xludf.DUMMYFUNCTION("sum(filter('PLA Sheet'!J:J,'PLA Sheet'!C:C=B35,'PLA Sheet'!D:D=C35))/E35*9"),2.0042212080717587) -> 2.0042212 | H35: 0.5443038 | I35: 0.15551537 | J35: 0.30018083 | K35: =H35-J35 -> 0.24412296 | L35: 1.6429792 | M35: =('Cy Young Rank'!O$1-G35)*E35/9 -> 7.3707229
A36: Zack Wheeler | B36: 554430 | C36: FF | D36: 951 | E36: =IFERROR(__xludf.DUMMYFUNCTION("sum(filter('PLA Sheet'!H:H,'PLA Sheet'!C:C=B36,'PLA Sheet'!D:D=C36))"),61.39209133999999) -> 61.392091 | F36: 5.5040429 | G36: =IFERROR(__xludf.DUMMYFUNCTION("sum(filter('PLA Sheet'!J:J,'PLA Sheet'!C:C=B36,'PLA Sheet'!D:D=C36))/E36*9"),2.1243752110953906) -> 2.1243752 | H36: 0.59516299 | I36: 0.12513144 | J36: 0.27970557 | K36: =H36-J36 -> 0.31545741 | L36: 4.1470053 | M36: =('Cy Young Rank'!O$1-G36)*E36/9 -> 13.203562
A37: Steven Okert | B37: 595345 | C37: SL | D37: 591 | E37: =IFERROR(__xludf.DUMMYFUNCTION("sum(filter('PLA Sheet'!H:H,'PLA Sheet'!C:C=B37,'PLA Sheet'!D:D=C37))"),41.41951838) -> 41.419518 | F37: 5.4978511 | G37: =IFERROR(__xludf.DUMMYFUNCTION("sum(filter('PLA Sheet'!J:J,'PLA Sheet'!C:C=B37,'PLA Sheet'!D:D=C37))/E37*9"),1.656094003090144) -> 1.656094 | H37: 0.56514382 | I37: 0.15905245 | J37: 0.27580372 | K37: =H37-J37 -> 0.2893401 | L37: 6.5210381 | M37: =('Cy Young Rank'!O$1-G37)*E37/9 -> 11.063181
A38: Tyler Alexander | B38: 641302 | C38: ST | D38: 346 | E38: =IFERROR(__xludf.DUMMYFUNCTION("sum(filter('PLA Sheet'!H:H,'PLA Sheet'!C:C=B38,'PLA Sheet'!D:D=C38))"),21.916350613) -> 21.916351 | F38: 5.496734 | G38: =IFERROR(__xludf.DUMMYFUNCTION("sum(filter('PLA Sheet'!J:J,'PLA Sheet'!C:C=B38,'PLA Sheet'!D:D=C38))/E38*9"),1.875623215099365) -> 1.8756232 | H38: 0.54046243 | I38: 0.18208093 | J38: 0.27745665 | K38: =H38-J38 -> 0.26300578 | L38: -11.843533 | M38: =('Cy Young Rank'!O$1-G38)*E38/9 -> 5.3192853
A39: Garrett Crochet | B39: 676979 | C39: FC | D39: 844 | E39: =IFERROR(__xludf.DUMMYFUNCTION("sum(filter('PLA Sheet'!H:H,'PLA Sheet'!C:C=B39,'PLA Sheet'!D:D=C39))"),57.138500638000004) -> 57.138501 | F39: 5.4943228 | G39: =IFERROR(__xludf.DUMMYFUNCTION("sum(filter('PLA Sheet'!J:J,'PLA Sheet'!C:C=B39,'PLA Sheet'!D:D=C39))/E39*9"),1.9320583628787378) -> 1.9320584 | H39: 0.6007109 | I39: 0.15876777 | J39: 0.24052133 | K39: =H39-J39 -> 0.36018957 | L39: 4.5727291 | M39: =('Cy Young Rank'!O$1-G39)*E39/9 -> 13.509711
A40: Shota Imanaga | B40: 684007 | C40: FF | D40: 1025 | E40: =IFERROR(__xludf.DUMMYFUNCTION("sum(filter('PLA Sheet'!H:H,'PLA Sheet'!C:C=B40,'PLA Sheet'!D:D=C40))"),70.33701318) -> 70.337013 | F40: 5.4938801 | G40: =IFERROR(__xludf.DUMMYFUNCTION("sum(filter('PLA Sheet'!J:J,'PLA Sheet'!C:C=B40,'PLA Sheet'!D:D=C40))/E40*9"),1.9166174380337828) -> 1.9166174 | H40: 0.60292683 | I40: 0.11707317 | J40: 0.28 | K40: =H40-J40 -> 0.32292683 | L40: -7.2337346 | M40: =('Cy Young Rank'!O$1-G40)*E40/9 -> 16.751014
...

Sheet Appearance (min 60)
A1: Pitcher | B1: MLBAMID | C1: Game Date | D1: Pitches | E1: IP | F1: PLV | G1: PLV Runs | H1: PLA | I1: Quality Pitch | J1: Average Pitch | K1: Bad Pitch | L1: QP-BP | M1: Hit Luck
A2: Freddy Peralta | B2: 642547 | C2: 45916 | D2: 88 | E2: =IFERROR(__xludf.DUMMYFUNCTION("average(filter('Appearance Sheet'!F:F,'Appearance Sheet'!G:G=B2,'Appearance Sheet'!A:A=C2))"),"#N/A") -> #N/A | F2: 5.8921163 | G2: 0.41445389 | H2: =G2*9/E2 -> #N/A | I2: 0.63636364 | J2: 0.21590909 | K2: 0.14772727 | L2: =I2-K2 -> 0.48863636 | M2: 3.5057395
A3: JP Sears | B3: 676664 | C3: 45848 | D3: 84 | E3: =IFERROR(__xludf.DUMMYFUNCTION("average(filter('Appearance Sheet'!F:F,'Appearance Sheet'!G:G=B3,'Appearance Sheet'!A:A=C3))"),"#N/A") -> #N/A | F3: 5.8668803 | G3: 0.39647894 | H3: =G3*9/E3 -> #N/A | I3: 0.60714286 | J3: 0.16666667 | K3: 0.22619048 | L3: =I3-K3 -> 0.38095238 | M3: 0.96882147
A4: Ryan Bergert | B4: 686701 | C4: 45891 | D4: 90 | E4: =IFERROR(__xludf.DUMMYFUNCTION("average(filter('Appearance Sheet'!F:F,'Appearance Sheet'!G:G=B4,'Appearance Sheet'!A:A=C4))"),"#N/A") -> #N/A | F4: 5.8414648 | G4: 0.52366684 | H4: =G4*9/E4 -> #N/A | I4: 0.65555556 | J4: 0.12222222 | K4: 0.22222222 | L4: =I4-K4 -> 0.43333333 | M4: 2.0130884
A5: Joe Ryan | B5: 657746 | C5: 45787 | D5: 74 | E5: =IFERROR(__xludf.DUMMYFUNCTION("average(filter('Appearance Sheet'!F:F,'Appearance Sheet'!G:G=B5,'Appearance Sheet'!A:A=C5))"),6.0) -> 6 | F5: 5.8410733 | G5: 0.44964231 | H5: =G5*9/E5 -> 0.67446346 | I5: 0.63513513 | J5: 0.13513513 | K5: 0.22972973 | L5: =I5-K5 -> 0.4054054 | M5: 1.5992453
A6: Sean Burke | B6: 680732 | C6: 45927 | D6: 79 | E6: =IFERROR(__xludf.DUMMYFUNCTION("average(filter('Appearance Sheet'!F:F,'Appearance Sheet'!G:G=B6,'Appearance Sheet'!A:A=C6))"),"#N/A") -> #N/A | F6: 5.8260422 | G6: 0.46132068 | H6: =G6*9/E6 -> #N/A | I6: 0.62025317 | J6: 0.11392405 | K6: 0.26582279 | L6: =I6-K6 -> 0.35443038 | M6: 1.4277364
A7: Jacob Misiorowski | B7: 694819 | C7: 45901 | D7: 72 | E7: =IFERROR(__xludf.DUMMYFUNCTION("average(filter('Appearance Sheet'!F:F,'Appearance Sheet'!G:G=B7,'Appearance Sheet'!A:A=C7))"),"#N/A") -> #N/A | F7: 5.8131244 | G7: 0.46190989 | H7: =G7*9/E7 -> #N/A | I7: 0.61111111 | J7: 0.13888889 | K7: 0.25 | L7: =I7-K7 -> 0.36111111 | M7: -2.0137995
A8: Jacob deGrom | B8: 594798 | C8: 45787 | D8: 87 | E8: =IFERROR(__xludf.DUMMYFUNCTION("average(filter('Appearance Sheet'!F:F,'Appearance Sheet'!G:G=B8,'Appearance Sheet'!A:A=C8))"),5.0) -> 5 | F8: 5.8022599 | G8: 0.56598211 | H8: =G8*9/E8 -> 1.0187678 | I8: 0.63218391 | J8: 0.16091954 | K8: 0.20689655 | L8: =I8-K8 -> 0.42528736 | M8: 0.027421489
A9: Ryan Weathers | B9: 677960 | C9: 45797 | D9: 79 | E9: =IFERROR(__xludf.DUMMYFUNCTION("average(filter('Appearance Sheet'!F:F,'Appearance Sheet'!G:G=B9,'Appearance Sheet'!A:A=C9))"),5.0) -> 5 | F9: 5.7927716 | G9: 0.52444023 | H9: =G9*9/E9 -> 0.94399241 | I9: 0.63291139 | J9: 0.13924051 | K9: 0.2278481 | L9: =I9-K9 -> 0.40506329 | M9: -0.60746272
A10: Jacob deGrom | B10: 594798 | C10: 45765 | D10: 93 | E10: =IFERROR(__xludf.DUMMYFUNCTION("average(filter('Appearance Sheet'!F:F,'Appearance Sheet'!G:G=B10,'Appearance Sheet'!A:A=C10))"),7.0) -> 7 | F10: 5.7631444 | G10: 0.70644831 | H10: =G10*9/E10 -> 0.90829068 | I10: 0.64516129 | J10: 0.15053763 | K10: 0.20430107 | L10: =I10-K10 -> 0.44086021 | M10: 1.9123075
A11: Jesús Luzardo | B11: 666200 | C11: 45900 | D11: 100 | E11: =IFERROR(__xludf.DUMMYFUNCTION("average(filter('Appearance Sheet'!F:F,'Appearance Sheet'!G:G=B11,'Appearance Sheet'!A:A=C11))"),"#N/A") -> #N/A | F11: 5.7522452 | G11: 0.73603509 | H11: =G11*9/E11 -> #N/A | I11: 0.59 | J11: 0.17 | K11: 0.24 | L11: =I11-K11 -> 0.35 | M11: 3.5484489
A12: Ryne Nelson | B12: 669194 | C12: 45776 | D12: 61 | E12: =IFERROR(__xludf.DUMMYFUNCTION("average(filter('Appearance Sheet'!F:F,'Appearance Sheet'!G:G=B12,'Appearance Sheet'!A:A=C12))"),4.0) -> 4 | F12: 5.7481184 | G12: 0.4333922 | H12: =G12*9/E12 -> 0.97513245 | I12: 0.67213115 | J12: 0.1147541 | K12: 0.21311475 | L12: =I12-K12 -> 0.45901639 | M12: 2.871533
A13: Ranger Suárez | B13: 624133 | C13: 45809 | D13: 93 | E13: =IFERROR(__xludf.DUMMYFUNCTION("average(filter('Appearance Sheet'!F:F,'Appearance Sheet'!G:G=B13,'Appearance Sheet'!A:A=C13))"),6.0) -> 6 | F13: 5.7461255 | G13: 0.74290088 | H13: =G13*9/E13 -> 1.1143513 | I13: 0.6344086 | J13: 0.13978495 | K13: 0.22580645 | L13: =I13-K13 -> 0.40860215 | M13: 0.86513022
A14: Zack Wheeler | B14: 554430 | C14: 45743 | D14: 93 | E14: =IFERROR(__xludf.DUMMYFUNCTION("average(filter('Appearance Sheet'!F:F,'Appearance Sheet'!G:G=B14,'Appearance Sheet'!A:A=C14))"),6.0) -> 6 | F14: 5.7459479 | G14: 0.68795889 | H14: =G14*9/E14 -> 1.0319383 | I14: 0.64516129 | J14: 0.10752688 | K14: 0.24731183 | L14: =I14-K14 -> 0.39784946 | M14: 3.1656538
A15: Chris Sale | B15: 519242 | C15: 45826 | D15: 113 | E15: =IFERROR(__xludf.DUMMYFUNCTION("average(filter('Appearance Sheet'!F:F,'Appearance Sheet'!G:G=B15,'Appearance Sheet'!A:A=C15))"),8.666666666666666) -> 8.6666667 | F15: 5.7243238 | G15: 0.90153629 | H15: =G15*9/E15 -> 0.93621076 | I15: 0.61061947 | J15: 0.16814159 | K15: 0.22123894 | L15: =I15-K15 -> 0.38938053 | M15: 2.6497242
A16: Cristopher Sánchez | B16: 650911 | C16: 45872 | D16: 81 | E16: =IFERROR(__xludf.DUMMYFUNCTION("average(filter('Appearance Sheet'!F:F,'Appearance Sheet'!G:G=B16,'Appearance Sheet'!A:A=C16))"),"#N/A") -> #N/A | F16: 5.721816 | G16: 0.69419014 | H16: =G16*9/E16 -> #N/A | I16: 0.61728395 | J16: 0.22222222 | K16: 0.16049383 | L16: =I16-K16 -> 0.45679012 | M16: 0.14818347
A17: Drew Rasmussen | B17: 656876 | C17: 45882 | D17: 76 | E17: =IFERROR(__xludf.DUMMYFUNCTION("average(filter('Appearance Sheet'!F:F,'Appearance Sheet'!G:G=B17,'Appearance Sheet'!A:A=C17))"),"#N/A") -> #N/A | F17: 5.7183337 | G17: 0.62809991 | H17: =G17*9/E17 -> #N/A | I17: 0.72368421 | J17: 0.14473684 | K17: 0.13157895 | L17: =I17-K17 -> 0.59210526 | M17: 1.5271255
A18: Mitch Spence | B18: 687765 | C18: 45824 | D18: 82 | E18: =IFERROR(__xludf.DUMMYFUNCTION("average(filter('Appearance Sheet'!F:F,'Appearance Sheet'!G:G=B18,'Appearance Sheet'!A:A=C18))"),5.0) -> 5 | F18: 5.7122269 | G18: 0.67086999 | H18: =G18*9/E18 -> 1.207566 | I18: 0.62195122 | J18: 0.1097561 | K18: 0.26829268 | L18: =I18-K18 -> 0.35365854 | M18: -1.9564509
A19: Pablo López | B19: 641154 | C19: 45743 | D19: 86 | E19: =IFERROR(__xludf.DUMMYFUNCTION("average(filter('Appearance Sheet'!F:F,'Appearance Sheet'!G:G=B19,'Appearance Sheet'!A:A=C19))"),5.0) -> 5 | F19: 5.6994804 | G19: 0.76714 | H19: =G19*9/E19 -> 1.380852 | I19: 0.59302326 | J19: 0.19767442 | K19: 0.20930233 | L19: =I19-K19 -> 0.38372093 | M19: -1.3684936
A20: Nick Pivetta | B20: 601713 | C20: 45776 | D20: 85 | E20: =IFERROR(__xludf.DUMMYFUNCTION("average(filter('Appearance Sheet'!F:F,'Appearance Sheet'!G:G=B20,'Appearance Sheet'!A:A=C20))"),5.333333333333333) -> 5.3333333 | F20: 5.6990694 | G20: 0.74789186 | H20: =G20*9/E20 -> 1.2620675 | I20: 0.64705882 | J20: 0.11764706 | K20: 0.23529412 | L20: =I20-K20 -> 0.41176471 | M20: -0.63340862
A21: Zack Wheeler | B21: 554430 | C21: 45783 | D21: 84 | E21: =IFERROR(__xludf.DUMMYFUNCTION("average(filter('Appearance Sheet'!F:F,'Appearance Sheet'!G:G=B21,'Appearance Sheet'!A:A=C21))"),7.0) -> 7 | F21: 5.6873379 | G21: 0.77731967 | H21: =G21*9/E21 -> 0.999411 | I21: 0.54761905 | J21: 0.26190476 | K21: 0.19047619 | L21: =I21-K21 -> 0.35714286 | M21: 0.89342727
A22: Zack Wheeler | B22: 554430 | C22: 45817 | D22: 101 | E22: =IFERROR(__xludf.DUMMYFUNCTION("average(filter('Appearance Sheet'!F:F,'Appearance Sheet'!G:G=B22,'Appearance Sheet'!A:A=C22))"),6.0) -> 6 | F22: 5.6865615 | G22: 0.86632375 | H22: =G22*9/E22 -> 1.2994856 | I22: 0.59405941 | J22: 0.16831683 | K22: 0.23762376 | L22: =I22-K22 -> 0.35643564 | M22: 2.4439463
A23: Sean Manaea | B23: 640455 | C23: 45851 | D23: 63 | E23: =IFERROR(__xludf.DUMMYFUNCTION("average(filter('Appearance Sheet'!F:F,'Appearance Sheet'!G:G=B23,'Appearance Sheet'!A:A=C23))"),"#N/A") -> #N/A | F23: 5.6837252 | G23: 0.56590282 | H23: =G23*9/E23 -> #N/A | I23: 0.55555556 | J23: 0.25396825 | K23: 0.19047619 | L23: =I23-K23 -> 0.36507937 | M23: -1.7403736
A24: Jacob Latz | B24: 656641 | C24: 45896 | D24: 64 | E24: =IFERROR(__xludf.DUMMYFUNCTION("average(filter('Appearance Sheet'!F:F,'Appearance Sheet'!G:G=B24,'Appearance Sheet'!A:A=C24))"),"#N/A") -> #N/A | F24: 5.6716953 | G24: 0.61057405 | H24: =G24*9/E24 -> #N/A | I24: 0.6875 | J24: 0.0625 | K24: 0.25 | L24: =I24-K24 -> 0.4375 | M24: -0.83500082
A25: Hunter Dobbins | B25: 690928 | C25: 45801 | D25: 70 | E25: =IFERROR(__xludf.DUMMYFUNCTION("average(filter('Appearance Sheet'!F:F,'Appearance Sheet'!G:G=B25,'Appearance Sheet'!A:A=C25))"),4.0) -> 4 | F25: 5.6669087 | G25: 0.66313817 | H25: =G25*9/E25 -> 1.4920609 | I25: 0.57142857 | J25: 0.18571429 | K25: 0.24285714 | L25: =I25-K25 -> 0.32857143 | M25: -1.3547923
A26: Luis Morales | B26: 806960 | C26: 45891 | D26: 94 | E26: =IFERROR(__xludf.DUMMYFUNCTION("average(filter('Appearance Sheet'!F:F,'Appearance Sheet'!G:G=B26,'Appearance Sheet'!A:A=C26))"),"#N/A") -> #N/A | F26: 5.6657527 | G26: 0.84468298 | H26: =G26*9/E26 -> #N/A | I26: 0.56382979 | J26: 0.19148936 | K26: 0.24468085 | L26: =I26-K26 -> 0.31914894 | M26: 3.5855466
A27: George Kirby | B27: 669923 | C27: 45833 | D27: 88 | E27: =IFERROR(__xludf.DUMMYFUNCTION("average(filter('Appearance Sheet'!F:F,'Appearance Sheet'!G:G=B27,'Appearance Sheet'!A:A=C27))"),6.0) -> 6 | F27: 5.66051 | G27: 0.80629529 | H27: =G27*9/E27 -> 1.2094429 | I27: 0.53409091 | J27: 0.26136364 | K27: 0.20454545 | L27: =I27-K27 -> 0.32954545 | M27: 1.7797782
A28: Joe Ryan | B28: 657746 | C28: 45888 | D28: 86 | E28: =IFERROR(__xludf.DUMMYFUNCTION("average(filter('Appearance Sheet'!F:F,'Appearance Sheet'!G:G=B28,'Appearance Sheet'!A:A=C28))"),"#N/A") -> #N/A | F28: 5.6590462 | G28: 0.7596841 | H28: =G28*9/E28 -> #N/A | I28: 0.52325581 | J28: 0.13953488 | K28: 0.3372093 | L28: =I28-K28 -> 0.18604651 | M28: -2.7513565
A29: Jack Flaherty | B29: 656427 | C29: 45910 | D29: 96 | E29: =IFERROR(__xludf.DUMMYFUNCTION("average(filter('Appearance Sheet'!F:F,'Appearance Sheet'!G:G=B29,'Appearance Sheet'!A:A=C29))"),"#N/A") -> #N/A | F29: 5.6568125 | G29: 0.84070737 | H29: =G29*9/E29 -> #N/A | I29: 0.5625 | J29: 0.10416667 | K29: 0.33333333 | L29: =I29-K29 -> 0.22916667 | M29: 2.7742685
A30: Sonny Gray | B30: 543243 | C30: 45796 | D30: 88 | E30: =IFERROR(__xludf.DUMMYFUNCTION("average(filter('Appearance Sheet'!F:F,'Appearance Sheet'!G:G=B30,'Appearance Sheet'!A:A=C30))"),6.0) -> 6 | F30: 5.6568059 | G30: 0.80124964 | H30: =G30*9/E30 -> 1.2018745 | I30: 0.61363636 | J30: 0.125 | K30: 0.26136364 | L30: =I30-K30 -> 0.35227273 | M30: 2.1482673
A31: Paul Skenes | B31: 694973 | C31: 45795 | D31: 101 | E31: =IFERROR(__xludf.DUMMYFUNCTION("average(filter('Appearance Sheet'!F:F,'Appearance Sheet'!G:G=B31,'Appearance Sheet'!A:A=C31))"),8.0) -> 8 | F31: 5.6548927 | G31: 0.94106471 | H31: =G31*9/E31 -> 1.0586978 | I31: 0.64356436 | J31: 0.15841584 | K31: 0.1980198 | L31: =I31-K31 -> 0.44554455 | M31: 2.7498775
A32: Garrett Crochet | B32: 676979 | C32: 45892 | D32: 101 | E32: =IFERROR(__xludf.DUMMYFUNCTION("average(filter('Appearance Sheet'!F:F,'Appearance Sheet'!G:G=B32,'Appearance Sheet'!A:A=C32))"),"#N/A") -> #N/A | F32: 5.6537855 | G32: 0.97603694 | H32: =G32*9/E32 -> #N/A | I32: 0.61386139 | J32: 0.11881188 | K32: 0.26732673 | L32: =I32-K32 -> 0.34653465 | M32: 2.7413963
A33: Janson Junk | B33: 676083 | C33: 45828 | D33: 78 | E33: =IFERROR(__xludf.DUMMYFUNCTION("average(filter('Appearance Sheet'!F:F,'Appearance Sheet'!G:G=B33,'Appearance Sheet'!A:A=C33))"),5.0) -> 5 | F33: 5.6533599 | G33: 0.75845769 | H33: =G33*9/E33 -> 1.3652238 | I33: 0.57692308 | J33: 0.23076923 | K33: 0.19230769 | L33: =I33-K33 -> 0.38461538 | M33: -0.003014538
A34: Aaron Nola | B34: 605400 | C34: 45926 | D34: 86 | E34: =IFERROR(__xludf.DUMMYFUNCTION("average(filter('Appearance Sheet'!F:F,'Appearance Sheet'!G:G=B34,'Appearance Sheet'!A:A=C34))"),"#N/A") -> #N/A | F34: 5.6487124 | G34: 0.88932511 | H34: =G34*9/E34 -> #N/A | I34: 0.63953488 | J34: 0.13953488 | K34: 0.22093023 | L34: =I34-K34 -> 0.41860465 | M34: 3.7514465
A35: Jack Leiter | B35: 683004 | C35: 45749 | D35: 68 | E35: =IFERROR(__xludf.DUMMYFUNCTION("average(filter('Appearance Sheet'!F:F,'Appearance Sheet'!G:G=B35,'Appearance Sheet'!A:A=C35))"),5.0) -> 5 | F35: 5.6462648 | G35: 0.65768927 | H35: =G35*9/E35 -> 1.1838407 | I35: 0.60294118 | J35: 0.11764706 | K35: 0.27941176 | L35: =I35-K35 -> 0.32352941 | M35: 2.381925
A36: Logan Webb | B36: 657277 | C36: 45886 | D36: 85 | E36: =IFERROR(__xludf.DUMMYFUNCTION("average(filter('Appearance Sheet'!F:F,'Appearance Sheet'!G:G=B36,'Appearance Sheet'!A:A=C36))"),"#N/A") -> #N/A | F36: 5.6434948 | G36: 0.84452869 | H36: =G36*9/E36 -> #N/A | I36: 0.57647059 | J36: 0.23529412 | K36: 0.18823529 | L36: =I36-K36 -> 0.38823529 | M36: 2.4280721
A37: Cole Ragans | B37: 666142 | C37: 45793 | D37: 83 | E37: =IFERROR(__xludf.DUMMYFUNCTION("average(filter('Appearance Sheet'!F:F,'Appearance Sheet'!G:G=B37,'Appearance Sheet'!A:A=C37))"),5.0) -> 5 | F37: 5.6432288 | G37: 0.80945942 | H37: =G37*9/E37 -> 1.457027 | I37: 0.56626506 | J37: 0.18072289 | K37: 0.25301205 | L37: =I37-K37 -> 0.31325301 | M37: -0.18413777
A38: Yoshinobu Yamamoto | B38: 808967 | C38: 45893 | D38: 92 | E38: =IFERROR(__xludf.DUMMYFUNCTION("average(filter('Appearance Sheet'!F:F,'Appearance Sheet'!G:G=B38,'Appearance Sheet'!A:A=C38))"),"#N/A") -> #N/A | F38: 5.6386871 | G38: 0.92368816 | H38: =G38*9/E38 -> #N/A | I38: 0.55434783 | J38: 0.17391304 | K38: 0.27173913 | L38: =I38-K38 -> 0.2826087 | M38: 1.1536812
